Workbook

Sheet 1. DB_Experiment_VER1
C1: SABIC | D1: KRICT (5.8%) | E1: KRICT (10%) | F1: KRICT (20%) | G1: KRICT (30%) | H1: KRICT (업데이트 실험결과)
A2: Reference | C2: PCT/US2018/012064
C3: US 7,919,431 B2
A4: Preheating | J4: lb | K4: g
A5: Temp (oC) | C5: 500 | D5: - | J5: 1 | K5: 453.592
A7: CH4 pyrolysis | J7: 43.5
A8: Temp (oC) | C8: 2500 | D8: 1114 | E8: 1114 | F8: 1114 | G8: 1114 | H8: 1230
A9: CH4 feed (lb/h) | C9: 43.5
A10: CH4 feed (g/h) | C10: =C9*K5 -> 19731.252
A11: CH4 feed (ml/min) | D11: 20 | E11: 20 | F11: 20 | G11: 20 | H11: 14.4
A12: CH4 feed (mol/h) | C12: =C10/16 -> 1233.2033 | D12: =D11*60/22400 -> 0.053571429 | E12: =E11*60/22400 -> 0.053571429 | F12: =F11*60/22400 -> 0.053571429 | G12: =G11*60/22400 -> 0.053571429 | H12: =H11*60/22400 -> 0.038571429
A13: H2 feed (ml/min) | D13: 60 | E13: 60 | F13: 60 | G13: 60 | H13: 64
A14: H2 feed (mol/h) | D14: =D13*60/22400 -> 0.16071429 | E14: =E13*60/22400 -> 0.16071429 | F14: =F13*60/22400 -> 0.16071429 | G14: =G13*60/22400 -> 0.16071429 | H14: =H13*60/22400 -> 0.17142857 | I14: H2/CH4 | J14: =H14/H12 -> 4.4444444
A15: CH4 fuel (lb/h) | C15: 55.6
A16: CH4 fuel (g/h) | C16: =C15*K5 -> 25219.715
A17: CH4 fuel (mol/h) | C17: =C16/16 -> 1576.2322
A18: Pure O2 (lb/h) | C18: 182.8
A19: O2 fuel (g/h) | C19: =C18*K5 -> 82916.618
A20: O2 fuel (mol/h) | C20: =C19/32 -> 2591.1443
A21: Duty (Mbtu/h) | C21: 1114
A22: O2 stoichometry (%) | C22: 88.4
A27: Methane conversion (%) | C27: 51.3 | D27: 5.8 | E27: 10 | F27: 20 | G27: 30 | H27: 30.353963
A29: Product composition (C%)
A30: C2H6 | D30: 5.5 | E30: 5.5 | F30: 5.5 | G30: 5.5 | H30: 1.9832376
A31: C2H4 | D31: 60.3 | E31: 60.3 | F31: 60.3 | G31: 60.3 | H31: 35.180966
A32: C2H2 | D32: 2.9 | E32: 2.9 | F32: 2.9 | G32: 2.9 | H32: 41.411786
A33: C3-C5 | D33: 1.3 | E33: 1.3 | F33: 1.3 | G33: 1.3 | H33: 0
A34: Benzene | D34: 4.3 | E34: 4.3 | F34: 4.3 | G34: 4.3 | H34: 7.4789878
A35: Naphthalene | D35: 25.6 | E35: 25.6 | F35: 25.6 | G35: 25.6 | H35: 2.6768978
A36: Coke | H36: 11.268125
A37: Total | D37: =SUM(D30:D35) -> 99.9 | E37: =SUM(E30:E35) -> 99.9 | F37: =SUM(F30:F35) -> 99.9 | G37: =SUM(G30:G35) -> 99.9 | H37: =SUM(H30:H36) -> 100
L38: -253 | M38: Hydrogen in hydrocarbon | N38: 1 CASE | O38: 2 CASE | P38: 3 CASE | Q38: 4 CASE | R38: KRICT (업데이트 실험결과)
A39: Product composition (mol/h) (1) | L39: -164 | M39: CH4 | N39: =D12*D27/100*2 -> 0.0062142857 | O39: =E12*E27/100*2 -> 0.010714286 | P39: =F12*F27/100*2 -> 0.021428571 | Q39: =G12*G27/100*2 -> 0.032142857 | R39: =H12*H27/100*2 -> 0.023415914 | S39: =Q39/$Q$48*100 -> 48.056122
A40: H2 | C40: =$C$42*C54/$C$56 -> 1544.3952 | D40: =D14+N47 -> 0.1643282 | E40: =E14+O47 -> 0.1688282 | F40: =F14+P47 -> 0.17954249 | G40: =G14+Q47 -> 0.19025678 | H40: =H14+R47 -> 0.1873898 | I40: =H40*10000 -> 1873.898 | L40: -89 | M40: C2H6 | N40: =D43*3 -> 0.00025633929 | O40: =E43*3 -> 0.00025633929 | P40: =F43*3 -> 0.00025633929 | Q40: =G43*3 -> 0.00025633929 | R40: =H43*3 -> 0.0003482949 | S40: =Q40/$Q$48*100 -> 0.38324757
A41: CO2 | C41: =$C$42*C55/$C$56 -> 859.26123 | I41: =H41*10000 -> 0 | L41: -104 | M41: C2H4 | N41: =D44*2 -> 0.0018736071 | O41: =E44*2 -> 0.0018736071 | P41: =F44*2 -> 0.0018736071 | Q41: =G44*2 -> 0.0018736071 | R41: =H44*2 -> 0.0041189724 | S41: =Q41/$Q$48*100 -> 2.8011913
A42: CH4 | C42: =C12*C27/100 -> 632.63327 | D42: =D12*(100-D27)/100 -> 0.050464286 | E42: =E12*(100-E27)/100 -> 0.048214286 | F42: =F12*(100-F27)/100 -> 0.042857143 | G42: =G12*(100-G27)/100 -> 0.0375 | H42: =H12*(100-H27)/100 -> 0.026863472 | I42: =H42*10000 -> 268.63472 | L42: -84 | M42: C2H2 | N42: =D45*1 -> 4.5053571e-05 | O42: =E45*1 -> 4.5053571e-05 | P42: =F45*1 -> 4.5053571e-05 | Q42: =G45*1 -> 4.5053571e-05 | R42: =H45*1 -> 0.002424237 | S42: =Q42/$Q$48*100 -> 0.067358664
A43: C2H6 | D43: =($D$12-$D$42)*D30/100/2 -> 8.5446429e-05 | E43: =($D$12-$D$42)*E30/100/2 -> 8.5446429e-05 | F43: =($D$12-$D$42)*F30/100/2 -> 8.5446429e-05 | G43: =($D$12-$D$42)*G30/100/2 -> 8.5446429e-05 | H43: =($H$12-$H$42)*H30/100/2 -> 0.0001160983 | I43: =H43*10000 -> 1.160983 | L43: -84 | M43: C3-C5 | N43: =D46*3 -> 4.0392857e-05 | O43: =E46*3 -> 4.0392857e-05 | P43: =F46*3 -> 4.0392857e-05 | Q43: =G46*3 -> 4.0392857e-05 | R43: =H46*3 -> 0 | S43: =Q43/$Q$48*100 -> 0.060390526
A44: C2H4 | C44: =$C$42*C58/$C$56 -> 21.000274 | D44: =($D$12-$D$42)*D31/100/2 -> 0.00093680357 | E44: =($D$12-$D$42)*E31/100/2 -> 0.00093680357 | F44: =($D$12-$D$42)*F31/100/2 -> 0.00093680357 | G44: =($D$12-$D$42)*G31/100/2 -> 0.00093680357 | H44: =($H$12-$H$42)*H31/100/2 -> 0.0020594862 | I44: =H44*10000 -> 20.594862 | L44: -47 -> 36 | M44: Benzene | N44: =D47*3 -> 6.6803571e-05 | O44: =E47*3 -> 6.6803571e-05 | P44: =F47*3 -> 6.6803571e-05 | Q44: =G47*3 -> 6.6803571e-05 | R44: =H47*3 -> 0.00043781834 | S44: =Q44/$Q$48*100 -> 0.09987664
A45: C2H2 | C45: =$C$42*C59/$C$56 -> 200.37762 | D45: =($D$12-$D$42)*D32/100/2 -> 4.5053571e-05 | E45: =($D$12-$D$42)*E32/100/2 -> 4.5053571e-05 | F45: =($D$12-$D$42)*F32/100/2 -> 4.5053571e-05 | G45: =($D$12-$D$42)*G32/100/2 -> 4.5053571e-05 | H45: =($H$12-$H$42)*H32/100/2 -> 0.002424237 | I45: =H45*10000 -> 24.24237 | L45: 80 | M45: Naphthalene | N45: =D48*4 -> 0.00031817143 | O45: =E48*4 -> 0.00031817143 | P45: =F48*4 -> 0.00031817143 | Q45: =G48*4 -> 0.00031817143 | R45: =H48*4 -> 0.00012536402 | S45: =Q45/$Q$48*100 -> 0.47569153
A46: C3-C5 | D46: =($D$12-$D$42)*D33/100/3 -> 1.3464286e-05 | E46: =($D$12-$D$42)*E33/100/3 -> 1.3464286e-05 | F46: =($D$12-$D$42)*F33/100/3 -> 1.3464286e-05 | G46: =($D$12-$D$42)*G33/100/3 -> 1.3464286e-05 | H46: =($H$12-$H$42)*H33/100/3 -> 0 | I46: =H46*10000 -> 0 | L46: 218 | M46: H2 | N46: =SUM(N40:N45) -> 0.0026003679 | O46: =SUM(O40:O45) -> 0.0026003679 | P46: =SUM(P40:P45) -> 0.0026003679 | Q46: =SUM(Q40:Q45) -> 0.0026003679 | R46: =SUM(R40:R45) -> 0.0074546866 | S46: =(Q46+Q47)/Q48*100 -> 48.056122
...

Sheet 1. DB_Experiment_VER2
C1: KRICT (previous data) | D1: KRICT (current data)
A2: Reference
A4: Preheating | J4: lb | K4: g
A5: Temp (oC) | J5: 1 | K5: 453.592
A7: CH4 pyrolysis | C7: O | D7: O | E7: O | F7: O | G7: O | J7: 43.5
A8: Temp (oC) | C8: 1230 | D8: 1230 | E8: 1230 | F8: 1230 | G8: 1230 | H8: 1150
A9: CH4 feed (lb/h)
A10: CH4 feed (g/h)
A11: CH4 feed (ml/min) | C11: 14.4 | D11: 14.4 | E11: 22.5 | F11: 45 | G11: 162
A12: CH4 feed (mol/h) | C12: =C11*60/22400 -> 0.038571429 | D12: =D11*60/22400 -> 0.038571429 | E12: =E11*60/22400 -> 0.060267857 | F12: =F11*60/22400 -> 0.12053571 | G12: =G11*60/22400 -> 0.43392857
A13: H2 feed (ml/min) | C13: 64 | D13: 65.6 | E13: 77.5 | F13: 105 | G13: 198
A14: H2 feed (mol/h) | C14: =C13*60/22400 -> 0.17142857 | D14: =D13*60/22400 -> 0.17571429 | E14: =E13*60/22400 -> 0.20758929 | F14: =F13*60/22400 -> 0.28125 | G14: =G13*60/22400 -> 0.53035714 | I14: H2/CH4 | J14: =C14/C12 -> 4.4444444 | K14: =D14/D12 -> 4.5555556 | L14: =E14/E12 -> 3.4444444 | M14: =F14/F12 -> 2.3333333 | N14: =G14/G12 -> 1.2222222 | O14: 2.5
A15: CH4 fuel (lb/h) | J15: =J14*3663 -> 16280 | K15: =K14*3663 -> 16687
A16: CH4 fuel (g/h)
A17: CH4 fuel (mol/h) | I17: [Carbon]
A18: Pure O2 (lb/h) | I18: CH4 | J18: =C45 -> 0.026863472 | K18: =D45 -> 0.027989396 | L18: =E45 -> 0.041616556 | M18: =F45 -> 0.082340326 | N18: =G45 -> 0.31211678
A19: O2 fuel (g/h) | I19: C2H6 | J19: =C46*2 -> 0.0002321966 | K19: =D46*2 -> 0.00063791607 | L19: =E46*2 -> 0.00081582931 | M19: =F46*2 -> 0.0013307041 | N19: =G46*2 -> 0.0036049504
A20: O2 fuel (mol/h) | I20: C2H4 | J20: =C47*2 -> 0.0041189724 | K20: =D47*2 -> 0.0084717494 | L20: =E47*2 -> 0.013754806 | M20: =F47*2 -> 0.026454735 | N20: =G47*2 -> 0.076315145
A21: Duty (Mbtu/h) | I21: C2H2 | J21: =C48*2 -> 0.0048484741 | K21: =D48*2 -> 0 | L21: =E48*2 -> 0 | M21: =F48*2 -> 0 | N21: =G48*2 -> 0.00034907813
A22: O2 stoichometry (%) | I22: C3-C5 | J22: =C49*3 -> 0 | K22: =D49*3 -> 0.00011935238 | L22: =E49*3 -> 0.0002325979 | M22: =F49*3 -> 0.00063994831 | N22: =G49*3 -> 0.0029762308
I23: Benzene | J23: =C50*6 -> 0.00087563668 | K23: =D50*6 -> 0.00087970214 | L23: =E50*6 -> 0.0020476513 | M23: =F50*6 -> 0.005455672 | N23: =G50*6 -> 0.02146341
A24: Low temp hydrogenation (temperature control by thermal gradient of CH4 pyrolysis zone in a single tube reactor) | C24: X | D24: O | E24: O | F24: O | G24: O | H24: O | I24: Toluene | J24: =C51*7 -> 0 | K24: =D51*7 -> 1.1922658e-05 | L24: =E51*7 -> 3.2852261e-05 | M24: =F51*7 -> 0.00011618638 | N24: =G51*7 -> 0.00083245596
A25: Temp (oC) | D25: 200 | E25: 200 | F25: 200 | G25: 200 | H25: 200 | I25: Naphthalene | J25: =C52*10 -> 0.00031341004 | K25: =D52*10 -> 0.00010564422 | L25: =E52*10 -> 0.00030244964 | M25: =F52*10 -> 0.00096099069 | N25: =G52*10 -> 0.0043561429
A26: Catalyst (Pd content on wall coated (umol) | D26: 1.532 | E26: 1.532 | F26: 1.532 | G26: 1.532 | H26: 1.532 | I26: C | J26: =C53 -> 0.00065963364 | K26: =D53 -> 0.00031596139 | L26: =E53 -> 0.0013875819 | M26: =F53 -> 0.0030238356 | N26: =G53 -> 0.010922306
I27: Total CH4 reacted | J27: =SUM(J19:J26) -> 0.011048323 | K27: =SUM(K19:K26) -> 0.010542248 | L27: =SUM(L19:L26) -> 0.018573768 | M27: =SUM(M19:M26) -> 0.037982072 | N27: =SUM(N19:N26) -> 0.12081972
J29: Previous (2019) | K29: Current data (2021)
A30: Methane conversion (%) | C30: 30.353963 | D30: 27.434899 | E30: 30.947344 | F30: 31.688026 | G30: 28.071854 | H30: 20 | I30: Selectivity(Carbon%) | J30: 4.4444444 | K30: 4.5555556 | L30: 3.4444444 | M30: 2.3333333 | N30: 1.2222222
I31: C2H6 | J31: =J19/J$27 -> 0.021016456 | K31: =K19/K$27 -> 0.06051044 | L31: =L19/L$27 -> 0.043923737 | M31: =M19/M$27 -> 0.035035058 | N31: =N19/N$27 -> 0.029837434 | P31: Ethylene yield
A32: Product composition (C%) | I32: C2H4 | J32: =J20/J$27 -> 0.37281425 | K32: =K20/K$27 -> 0.80359988 | L32: =L20/L$27 -> 0.7405501 | M32: =M20/M$27 -> 0.69650584 | N32: =N20/N$27 -> 0.63164478 | P32: =D30*K32 -> 22.046681 | Q32: =E30*L32 -> 22.918059 | R32: =F30*M32 -> 22.070895 | S32: =G30*N32 -> 17.73144
A33: C2H6 | C33: 1.9832376 | D33: 6.0282945 | E33: 4.3741148 | F33: 3.4839392 | G33: 2.9594428 | H33: 3.4839392 | I33: C2H2 | J33: =J21/J$27 -> 0.43884252 | K33: =K21/K$27 -> 0 | L33: =L21/L$27 -> 0 | M33: =M21/M$27 -> 0 | N33: =N21/N$27 -> 0.002889248
A34: C2H4 | C34: 35.180966 | D34: 80.057867 | E34: 73.747167 | F34: 69.261595 | G34: 62.650045 | H34: 69.261595 | I34: C3-C5 | J34: =J22/J$27 -> 0 | K34: =K22/K$27 -> 0.01132134 | L34: =L22/L$27 -> 0.012522924 | M34: =M22/M$27 -> 0.016848694 | N34: =N22/N$27 -> 0.024633651
A35: C2H2 | C35: 41.411786 | D35: 0 | E35: 0 | F35: 0 | G35: 0.28657169 | H35: 0 | I35: Benzene | J35: =J23/J$27 -> 0.079255164 | K35: =K23/K$27 -> 0.083445402 | L35: =L23/L$27 -> 0.11024426 | M35: =M23/M$27 -> 0.14363808 | N35: =N23/N$27 -> 0.17764824
A36: C3-C5 | C36: 0 | D36: 1.5038369 | E36: 1.6627823 | F36: 2.2339462 | G36: 3.2577369 | H36: 2.2339462 | I36: Toluene | J36: =J24/J$27 -> 0 | K36: =K24/K$27 -> 0.0011309408 | L36: =L24/L$27 -> 0.0017687451 | M36: =M24/M$27 -> 0.0030589796 | N36: =N24/N$27 -> 0.006890067
A37: Benzene | C37: 7.4789878 | D37: 8.3131681 | E37: 10.978598 | F37: 14.283588 | G37: 17.620141 | H37: 14.283588 | I37: Naphthalene | J37: =J25/J$27 -> 0.028367204 | K37: =K25/K$27 -> 0.010021033 | L37: =L25/L$27 -> 0.016283698 | M37: =M25/M$27 -> 0.025301166 | N37: =N25/N$27 -> 0.0360549
A38: Toluene | D38: 0.11266889 | E38: 0.17613925 | F38: 0.30418956 | G38: 0.68339519 | H38: 0.30418956 | I38: C | J38: =J26/J$27 -> 0.059704411 | K38: =K26/K$27 -> 0.029970969 | L38: =L26/L$27 -> 0.074706536 | M38: =M26/M$27 -> 0.079612183 | N38: =N26/N$27 -> 0.090401681
A39: Naphthalene | C39: 2.6768978 | D39: 0.9983358 | E39: 1.6216007 | F39: 2.5159862 | G39: 3.5761256 | H39: 2.5159862 | I39: Conversion | J39: =C30/100 -> 0.30353963 | K39: =D30/100 -> 0.27434899 | L39: =E30/100 -> 0.30947344 | M39: =F30/100 -> 0.31688026 | N39: =G30/100 -> 0.28071854
A40: Coke | C40: 11.268125 | D40: 2.985829 | E40: 7.4395984 | F40: 7.9167559 | G40: 8.9665419 | H40: 7.9167559
A41: Total | C41: =SUM(C33:C40) -> 100 | D41: =SUM(D33:D40) -> 100 | E41: =SUM(E33:E40) -> 100 | F41: =SUM(F33:F40) -> 100 | G41: =SUM(G33:G40) -> 100 | H41: =SUM(H33:H40) -> 100
M42: Hydrogen in hydrocarbon | N42: KRICT (previous data) | O42: KRICT (current data)
A43: Product composition (mol/h) (1) | M43: CH4 | N43: =C12*C30/100*2 -> 0.023415914 | O43: =D12*D30/100*2 -> 0.021164065 | P43: =E12*E30/100*2 -> 0.037302602 | Q43: =F12*F30/100*2 -> 0.076390776 | R43: =G12*G30/100*2 -> 0.24362359
...

Sheet 5. HEN_equip
A1: EQUIP.ICS (Equipment)
A3: Area Name | B3: Component Name | C3: Component Type | D3: Total Direct Cost | E3: Equipment Cost | F3: Equipment Weight | G3: Installed Weight
D4: (USD) | E4: (USD) | F4: LBS | G4: LBS
A11: R1 | B11: R1.RADIANT1 | C11: DHE TEMA EXCH
A12: R1 | B12: R1.M5 | C12: C | D12: 0 | E12: 0 | F12: 0 | G12: 0
A13: R1 | B13: R1.M402 | C13: C | D13: 0 | E13: 0 | F13: 0 | G13: 0
A14: R1 | B14: R1.DECOKING | C14: DAT REACTOR
A15: R1 | B15: R1.CONVECT2 | C15: DHE TEMA EXCH
A16: R1 | B16: R1.CONVECT1 | C16: DHE TEMA EXCH
A17: R1 | B17: R1.COMBUST | C17: DAT REACTOR
A18: R1 | B18: R1.B6 | C18: C | D18: 0 | E18: 0 | F18: 0 | G18: 0
A19: R1 | B19: R1.B1 | C19: DVT CYLINDER
A21: Miscellaneous Flowsheet Area | B21: VAL1 | C21: C | D21: 0 | E21: 0 | F21: 0 | G21: 0
A22: Miscellaneous Flowsheet Area | B22: V5-flash vessel | C22: DVT CYLINDER | D22: 449600 | E22: 165100 | F22: 77400 | G22: 123720
A23: Miscellaneous Flowsheet Area | B23: V4-flash vessel | C23: DVT CYLINDER | D23: 827300 | E23: 465200 | F23: 201800 | G23: 260882
A24: Miscellaneous Flowsheet Area | B24: V3-flash vessel | C24: DVT CYLINDER | D24: 812700 | E24: 583200 | F24: 245600 | G24: 284078
A25: Miscellaneous Flowsheet Area | B25: V2-flash vessel | C25: DVT CYLINDER | D25: 879100 | E25: 674200 | F25: 288900 | G25: 324361
A26: Miscellaneous Flowsheet Area | B26: V1-flash vessel | C26: DVT CYLINDER | D26: 3166900 | E26: 2366000 | F26: 1062700 | G26: 1216094
A27: Miscellaneous Flowsheet Area | B27: T3-bottoms split | C27: C | D27: 0 | E27: 0 | F27: 0 | G27: 0
A28: Miscellaneous Flowsheet Area | B28: T3-cond | C28: DHE TEMA EXCH | D28: 897800 | E28: 785600 | F28: 251000 | G28: 267561
A29: Miscellaneous Flowsheet Area | B29: T3-cond acc | C29: DHT HORIZ DRUM | D29: 348500 | E29: 58600 | F29: 17500 | G29: 60908
A30: Miscellaneous Flowsheet Area | B30: T3-overhead split | C30: C | D30: 0 | E30: 0 | F30: 0 | G30: 0
A31: Miscellaneous Flowsheet Area | B31: T3-reb | C31: DRB U TUBE | D31: 955000 | E31: 777800 | F31: 224700 | G31: 251939
A32: Miscellaneous Flowsheet Area | B32: T3-reflux pump | C32: DCP CENTRIF | D32: 116200 | E32: 33900 | F32: 2500 | G32: 15774
... A47: Miscellaneous Flowsheet Area | B47: T1-tower | C47: DTW TOWER | D47: 359100 | E47: 158600 | F47: 56300 | G47: 83523
A48: Miscellaneous Flowsheet Area | B48: MCOMP2 | C48: DGC CENTRIF
A49: Miscellaneous Flowsheet Area | B49: MCOMP1 | C49: DGC CENTRIF
A50: Miscellaneous Flowsheet Area | B50: M4 | C50: C | D50: 0 | E50: 0 | F50: 0 | G50: 0
A51: Miscellaneous Flowsheet Area | B51: M3 | C51: C | D51: 0 | E51: 0 | F51: 0 | G51: 0
A52: Miscellaneous Flowsheet Area | B52: M2 | C52: C | D52: 0 | E52: 0 | F52: 0 | G52: 0
A53: Miscellaneous Flowsheet Area | B53: M1 | C53: C | D53: 0 | E53: 0 | F53: 0 | G53: 0
A54: Miscellaneous Flowsheet Area | B54: HX1 | C54: DHE TEMA EXCH
A55: Miscellaneous Flowsheet Area | B55: E9 | C55: DHE TEMA EXCH | D55: 799000 | E55: 770000 | F55: 245500 | G55: 249322
A56: Miscellaneous Flowsheet Area | B56: E8 | C56: DHE TEMA EXCH | D56: 667300 | E56: 646300 | F56: 180000 | G56: 182261
A57: Miscellaneous Flowsheet Area | B57: E7 | C57: DHE TEMA EXCH | D57: 1435300 | E57: 1316700 | F57: 373600 | G57: 391318
A58: Miscellaneous Flowsheet Area | B58: E6 | C58: DHE TEMA EXCH | D58: 1191300 | E58: 1112400 | F58: 314800 | G58: 327046
A59: Miscellaneous Flowsheet Area | B59: E5 | C59: DHE TEMA EXCH | D59: 970300 | E59: 949000 | F59: 272400 | G59: 274711
A60: Miscellaneous Flowsheet Area | B60: E4 | C60: DHE TEMA EXCH | D60: 252900 | E60: 236100 | F60: 66900 | G60: 68962
A61: Miscellaneous Flowsheet Area | B61: E3 | C61: DHE TEMA EXCH
A62: Miscellaneous Flowsheet Area | B62: E2 | C62: DHE TEMA EXCH | D62: 17682200 | E62: 7976800 | F62: 1048800 | G62: 1675328
...

Sheet 3. UPC & MSP (fixed)
A1: 1. Assumption and parameters
B3: ASSUMPTION AND PARAMETERS
B4: Location | E4: North America
B5: System Cost Base Date | E5: 1Q 16
B6: Project Type | E6: Grass roots/Clear field
B7: Plant lifetime (y) | E7: 30
B8: Annual operating hours (h) | E8: 8000
B9: Depreciation method | E9: Straight line
B10: Interest rate (%) | E10: 0.08
B11: Tax rate (%) | E11: 0.35
B12: Operating charges [% of operating labor cost] | E12: 0.15
B13: Plant overhead [% of labor and maintenance costs] | E13: 0.25
B14: G&A [% of fixed-operating cost] | E14: 0.06
B15: Capital charge factor | E15: =E10*POWER(1+E10,E7)/(POWER(1+E10,E7)-1) -> 0.088827433
A18: 2. Production Costs, UPC, and MSP
E20: Previous | F20: Case 1 | G20: Case 2 | H20: Case 3 | I20: Case 4
B21: 1. Total capital investment cost (TCI) ($) | D21: =SUBTOTAL(9,D22:D36) -> 5.04 | E21: =SUBTOTAL(9,E22:E36) -> 2.5298291e+09 | F21: =SUBTOTAL(9,F22:F36) -> 3.0959305e+09 | G21: =SUBTOTAL(9,G22:G36) -> 2.2739022e+09 | H21: =SUBTOTAL(9,H22:H36) -> 1.9751287e+09 | I21: =SUBTOTAL(9,I22:I36) -> 1.7921087e+09
B22: 1.1. Direct plan cost | D22: =SUBTOTAL(9,D23:D30) -> 3.6 | E22: =SUBTOTAL(9,E23:E30) -> 1.8070208e+09 | F22: =SUBTOTAL(9,F23:F30) -> 2.2113789e+09 | G22: =SUBTOTAL(9,G23:G30) -> 1.6242158e+09 | H22: =SUBTOTAL(9,H23:H30) -> 1.4108062e+09 | I22: =SUBTOTAL(9,I23:I30) -> 1.2800776e+09
B23: Purchased equipment (PE) | D23: 1 | E23: 5.0195021e+08 | F23: 6.1427193e+08 | G23: 4.5117106e+08 | H23: 3.9189061e+08 | I23: 3.5557711e+08
B24: Equipment setting | D24: 0.47 | E24: =$D24*E$23/$D$23 -> 2.359166e+08 | F24: =$D24*F$23/$D$23 -> 2.8870781e+08 | G24: =$D24*G$23/$D$23 -> 2.120504e+08 | H24: =$D24*H$23/$D$23 -> 1.8418859e+08 | I24: =$D24*I$23/$D$23 -> 1.6712124e+08
B25: Instrumentation and control | D25: 0.36 | E25: =$D25*E$23/$D$23 -> 1.8070208e+08 | F25: =$D25*F$23/$D$23 -> 2.2113789e+08 | G25: =$D25*G$23/$D$23 -> 1.6242158e+08 | H25: =$D25*H$23/$D$23 -> 1.4108062e+08 | I25: =$D25*I$23/$D$23 -> 1.2800776e+08
B26: Piping | D26: 0.68 | E26: =$D26*E$23/$D$23 -> 3.4132614e+08 | F26: =$D26*F$23/$D$23 -> 4.1770491e+08 | G26: =$D26*G$23/$D$23 -> 3.0679632e+08 | H26: =$D26*H$23/$D$23 -> 2.6648561e+08 | I26: =$D26*I$23/$D$23 -> 2.4179244e+08
B27: Electrical installation | D27: 0.11 | E27: =$D27*E$23/$D$23 -> 55214523 | F27: =$D27*F$23/$D$23 -> 67569912 | G27: =$D27*G$23/$D$23 -> 49628817 | H27: =$D27*H$23/$D$23 -> 43107967 | I27: =$D27*I$23/$D$23 -> 39113483
B28: Building and building services | D28: 0.18 | E28: =$D28*E$23/$D$23 -> 90351038 | F28: =$D28*F$23/$D$23 -> 1.1056895e+08 | G28: =$D28*G$23/$D$23 -> 81210792 | H28: =$D28*H$23/$D$23 -> 70540310 | I28: =$D28*I$23/$D$23 -> 64003881
B29: Yard improvements | D29: 0.1 | E29: =$D29*E$23/$D$23 -> 50195021 | F29: =$D29*F$23/$D$23 -> 61427193 | G29: =$D29*G$23/$D$23 -> 45117106 | H29: =$D29*H$23/$D$23 -> 39189061 | I29: =$D29*I$23/$D$23 -> 35557711
B30: Services facilities | D30: 0.7 | E30: =$D30*E$23/$D$23 -> 3.5136515e+08 | F30: =$D30*F$23/$D$23 -> 4.2999035e+08 | G30: =$D30*G$23/$D$23 -> 3.1581975e+08 | H30: =$D30*H$23/$D$23 -> 2.7432343e+08 | I30: =$D30*I$23/$D$23 -> 2.4890398e+08
B31: 1.2. Indirect plant cost | D31: =SUBTOTAL(9,D32:D36) -> 1.44 | E31: =SUBTOTAL(9,E32:E36) -> 7.2280831e+08 | F31: =SUBTOTAL(9,F32:F36) -> 8.8455158e+08 | G31: =SUBTOTAL(9,G32:G36) -> 6.4968633e+08 | H31: =SUBTOTAL(9,H32:H36) -> 5.6432248e+08 | I31: =SUBTOTAL(9,I32:I36) -> 5.1203104e+08
B32: Engineering | D32: 0.33 | E32: =$D32*E$23/$D$23 -> 1.6564357e+08 | F32: =$D32*F$23/$D$23 -> 2.0270974e+08 | G32: =$D32*G$23/$D$23 -> 1.4888645e+08 | H32: =$D32*H$23/$D$23 -> 1.293239e+08 | I32: =$D32*I$23/$D$23 -> 1.1734045e+08
B33: Construction expenses | D33: 0.41 | E33: =$D33*E$23/$D$23 -> 2.0579959e+08 | F33: =$D33*F$23/$D$23 -> 2.5185149e+08 | G33: =$D33*G$23/$D$23 -> 1.8498014e+08 | H33: =$D33*H$23/$D$23 -> 1.6067515e+08 | I33: =$D33*I$23/$D$23 -> 1.4578662e+08
B34: Legal expenses | D34: 0.04 | E34: =$D34*E$23/$D$23 -> 20078008 | F34: =$D34*F$23/$D$23 -> 24570877 | G34: =$D34*G$23/$D$23 -> 18046843 | H34: =$D34*H$23/$D$23 -> 15675624 | I34: =$D34*I$23/$D$23 -> 14223085
B35: Contractor's fee | D35: 0.22 | E35: =$D35*E$23/$D$23 -> 1.1042905e+08 | F35: =$D35*F$23/$D$23 -> 1.3513982e+08 | G35: =$D35*G$23/$D$23 -> 99257634 | H35: =$D35*H$23/$D$23 -> 86215934 | I35: =$D35*I$23/$D$23 -> 78226965
B36: Contingency | D36: 0.44 | E36: =$D36*E$23/$D$23 -> 2.2085809e+08 | F36: =$D36*F$23/$D$23 -> 2.7027965e+08 | G36: =$D36*G$23/$D$23 -> 1.9851527e+08 | H36: =$D36*H$23/$D$23 -> 1.7243187e+08 | I36: =$D36*I$23/$D$23 -> 1.5645393e+08
B37: Annualized TCI | E37: =E21*$E$15 -> 2.2471822e+08 | F37: =F21*$E$15 -> 2.7500356e+08 | G37: =G21*$E$15 -> 2.0198489e+08 | H37: =H21*$E$15 -> 1.7544561e+08 | I37: =I21*$E$15 -> 1.5918841e+08
B39: 2. Total perationg cost ($) | E39: =SUBTOTAL(9,E40:E54) -> 1.2502726e+09 | F39: =SUBTOTAL(9,F40:F54) -> 1.5037352e+09 | G39: =SUBTOTAL(9,G40:G54) -> 1.1987966e+09 | H39: =SUBTOTAL(9,H40:H54) -> 1.004324e+09 | I39: =SUBTOTAL(9,I40:I54) -> 8.5671061e+08 | K39: Assumption | O39: Yeraly consumprtion (8000 hr/y) | V39: lb | W39: kg
B40: 2.1. Variable operating cost | E40: =SUBTOTAL(9,E41:E48) -> 1.2401759e+09 | F40: =SUBTOTAL(9,F41:F48) -> 1.4916324e+09 | G40: =SUBTOTAL(9,G41:G48) -> 1.1896068e+09 | H40: =SUBTOTAL(9,H41:H48) -> 9.9619288e+08 | I40: =SUBTOTAL(9,I41:I48) -> 8.4922809e+08 | L40: Value | M40: Unit price | N40: Weight factor | O40: Unit | P40: Previous | Q40: Case 1 | R40: Case 2 | S40: Case 3 | T40: Case 4 | V40: 1 | W40: 0.45359237
B41: Natural gas feedstock | E41: =P41*$L41*$N41 -> 3.0306628e+08 | F41: =Q41*$L41*$N41 -> 3.0306628e+08 | G41: =R41*$L41*$N41 -> 3.0306628e+08 | H41: =S41*$L41*$N41 -> 3.0306628e+08 | I41: =T41*$L41*$N41 -> 3.0306628e+08 | K41: Natural gas feedstock | L41: 3.27 | M41: $/MMBTU | N41: 1 | O41: MMBTU | P41: 92680819 | Q41: 92680819 | R41: =327437.649716956/28.263682*8000 -> 92680819 | S41: =327437.649716956/28.263682*8000 -> 92680819 | T41: =327437.649716956/28.263682*8000 -> 92680819 | V41: 1 MMBTU = 28.263682 m3 NG
B42: Fuel gas | E42: =P42*$L42*$N42 -> 1.4326561e+08 | F42: =Q42*$L42*$N42 -> 2.431001e+08 | G42: =R42*$L42*$N42 -> 1.8710409e+08 | H42: =S42*$L42*$N42 -> 1.5613069e+08 | I42: =T42*$L42*$N42 -> 1.3639264e+08 | K42: Fuel gas | L42: =L41 -> 3.27 | M42: $/MMBTU | N42: 1 | O42: MMBTU | P42: 43812113 | Q42: =262649.228386354/28.263682*8000 -> 74342537 | R42: =202150.247312389/28.263682*8000 -> 57218376 | S42: =168686.087475501/28.263682*8000 -> 47746387 | T42: =147360.785925464/28.263682*8000 -> 41710287 | V42: 1MMBTU=1055MJ, 4251 MMBTU, 0.85 ef by Gavin Towler book
B43: O2 | E43: =P43*$L43*$N43 -> 14335462 | F43: =Q43*$L43*$N43 -> 2.2096061e+08 | G43: =R43*$L43*$N43 -> 1.700659e+08 | H43: =S43*$L43*$N43 -> 1.419142e+08 | I43: =T43*$L43*$N43 -> 1.2397431e+08 | K43: O2 | L43: 40 | M43: $/ton | N43: 1 | O43: ton | P43: 358386.56 | Q43: =690501.918117916/1000*8000 -> 5524015.3 | R43: =531455.927757318/1000*8000 -> 4251647.4 | S43: =443481.876816915/1000*8000 -> 3547855 | T43: =387419.714371281/1000*8000 -> 3099357.7
B44: CW | E44: =P44*$L44*$N44 -> 1.0188414e+08 | F44: =Q44*$L44*$N44 -> 1.0007561e+08 | G44: =R44*$L44*$N44 -> 70529292 | H44: =S44*$L44*$N44 -> 53760234 | I44: =T44*$L44*$N44 -> 44886792 | K44: CW | L44: 0.03 | M44: $/ton | N44: 1 | O44: ton | P44: 3396138120 | Q44: 3335853552 | R44: 2350976388 | S44: 1792007796 | T44: 1496226396
B45: Electricity | E45: =P45*$L45*$N45 -> 5.7882009e+08 | F45: =Q45*$L45*$N45 -> 5.693438e+08 | G45: =R45*$L45*$N45 -> 4.1372467e+08 | H45: =S45*$L45*$N45 -> 2.994831e+08 | I45: =T45*$L45*$N45 -> 1.9299286e+08 | K45: Electricity | L45: 0.069 | M45: $/kWh | N45: 1 | O45: kWh | P45: 8388696888 | Q45: 8251359360 | R45: 5996009760 | S45: 4340334720 | T45: 2796997920
...

Sheet Previous_Technical performance
B2: Catlatyst performance (conversion, selectivity) | H2: BOILING TEMPERATURE AT 1ATM (°C)
E3: Experiment | F3: Aspen (checked) | H3: H2 | J3: -253
B4: Reactor inlet: H2/CH4 ratio | E4: ='1. DB_Experiment_VER1'!$J$14 -> 4.4444444 | F4: =F47/F48 -> 4.4443999 | H4: CH4 | J4: -164
B5: Conversion (%) | E5: 30.353963 | F5: =(F48-G48)/F48*100 -> 30.350448 | H5: C2H6 | J5: -89
B6: Selectivity (%) | E6: =SUM(E7:E12) -> 100 | F6: =SUM(F7:F12) -> 100.01719 | H6: C2H4 | J6: -104
C7: C2H6 | E7: 1.9832376 | F7: =(G49-F49)*2/($F$48-$G$48)*100 -> 1.9835724 | H7: C2H2 | J7: -84
C8: C2H4 | E8: 35.180966 | F8: =(G50-F50)*2/($F$48-$G$48)*100 -> 35.187281 | H8: C3-C5 | J8: -84
C9: C2H2 | E9: 41.411786 | F9: =(G51-F51)*2/($F$48-$G$48)*100 -> 41.418759 | H9: Benzene | J9: -47~36
C10: Benzene | E10: 7.4789878 | F10: =(G53-F53)*6/($F$48-$G$48)*100 -> 7.4802315 | H10: Naphthalene | J10: 80
C11: Naphthalene | E11: 2.6768978 | F11: =(G54-F54)*10/($F$48-$G$48)*100 -> 2.6773429
C12: Coke | E12: 11.268125 | F12: =N55/($F$48-$G$48)*100 -> 11.269999 | H12: PRODUCT STREAM (KG/H) | K12: ton/y | L12: MT/y | M12: CH4Fd ton/y | S12: Mole flowrate (kmol/h) | T12: Mass flow rate (kg/h)
B13: Yields (%) | E13: =SUM(E14:E19) -> 30.355664 | H13: Ethylene (99.9% vol) | J13: =H59 -> 60867.667 | K13: =J13*8000/1000 -> 486941.33 | L13: =J13*8000/10^9 -> 0.48694133 | M13: =D59*8 -> 1692421.3 | R13: Raw materials
C14: C2H6 | E14: =F7*$F$5/100 -> 0.60202309 | H14: Acethylene (95.1 %vol) | J14: =I59 -> 70796.472 | K14: =J14*8000/1000 -> 566371.78 | L14: =J14*8000/10^9 -> 0.56637178 | R14: Methane | S14: =D46 -> 13186.8 | T14: =D59 -> 211552.67
C15: C2H4 | E15: =F8*$F$5/100 -> 10.679497 | H15: Naphthalene (95.7 %wt) | J15: =J59 -> 4312.9738 | K15: =J15*8000/1000 -> 34503.79 | L15: =J15*8000/10^9 -> 0.03450379 | R15: Products
C16: C2H2 | E16: =F9*$F$5/100 -> 12.570779 | H16: Benzene (99 %wt) | J16: =K59 -> 11415.992 | K16: =J16*8000/1000 -> 91327.939 | L16: =J16*8000/10^9 -> 0.091327939 | R16: Ethylene (99.9% vol) | S16: =H46 -> 2170.0515 | T16: 60867.667
C17: Benzene | E17: =F10*$F$5/100 -> 2.2702838 | H17: Hydrogen (96 %vol) | J17: =L59 -> 43795.087 | K17: =J17*8000/1000 -> 350360.7 | L17: =J17*8000/10^9 -> 0.3503607 | R17: Acethylene (95.1 %vol) | S17: =I46 -> 2685.8454 | T17: 70796.472
C18: Naphthalene | E18: =F11*$F$5/100 -> 0.81258557 | R18: Naphthalene (95.7 %wt) | S18: =J46 -> 35.101909 | T18: 4312.9738
C19: Coke | E19: =F12*$F$5/100 -> 3.4204952 | R19: Benzene (99 %wt) | S19: =K46 -> 145.59242 | T19: 11415.992
R20: Hydrogen (96 %vol) | S20: =L46 -> 17390.595 | T20: 43795.087
B44: MAJOR STREAM INFORMATION
D45: ='DB_Aspen simulation_previous'!D117 -> 1-CH4 | E45: ='DB_Aspen simulation_previous'!E117 -> 50-O2 | F45: ='DB_Aspen simulation_previous'!F117 -> 6-RXNin | G45: ='DB_Aspen simulation_previous'!G117 -> 7-RXN-out | H45: ='DB_Aspen simulation_previous'!H117 -> 27-Ethylene | I45: ='DB_Aspen simulation_previous'!I117 -> 28-C2 | J45: ='DB_Aspen simulation_previous'!J117 -> 12-Naphthalene | K45: ='DB_Aspen simulation_previous'!K117 -> 20-Benzene | ... N45: ='DB_Aspen simulation_previous'!N117 -> 49-COKE
B46: ='DB_Aspen simulation_previous'!B118 -> Mole Flows | C46: ='DB_Aspen simulation_previous'!C118 -> kmol/hr | D46: ='DB_Aspen simulation_previous'!D118 -> 13186.8 | E46: ='DB_Aspen simulation_previous'!E118 -> 1400 | F46: ='DB_Aspen simulation_previous'!F118 -> 221973.91 | G46: ='DB_Aspen simulation_previous'!G118 -> 231437.85 | H46: ='DB_Aspen simulation_previous'!H118 -> 2170.0515 | I46: ='DB_Aspen simulation_previous'!I118 -> 2685.8454 | ... N46: ='DB_Aspen simulation_previous'!N118 -> 1392.0025 | R46: 13186.8 | S46: 1400 | T46: 221973.91 | U46: 231437.85 | V46: 2170.0515 | W46: 2685.8454 | X46: 35.101909 | Y46: 145.59242 | Z46: 17390.595 | AA46: 1400 | AB46: 1392.0025
B47: ='DB_Aspen simulation_previous'!B119 -> H2 | C47: ='DB_Aspen simulation_previous'!C119 -> kmol/hr | D47: ='DB_Aspen simulation_previous'!D119 -> 0 | E47: ='DB_Aspen simulation_previous'!E119 -> 0 | F47: ='DB_Aspen simulation_previous'!F119 -> 180869.01 | G47: ='DB_Aspen simulation_previous'!G119 -> 197643.84 | H47: ='DB_Aspen simulation_previous'!H119 -> 1.0538853e-09 | I47: ='DB_Aspen simulation_previous'!I119 -> 2.1702471e-39 | ... N47: ='DB_Aspen simulation_previous'!N119 -> 0 | R47: 0 | S47: 0 | T47: 180869.01 | U47: 197643.84 | V47: 1.0538853e-09 | W47: 2.1702471e-39 | X47: 0.20996271 | Y47: 5.7435524e-08 | Z47: 16767.799 | AA47: 0 | AB47: 0
B48: ='DB_Aspen simulation_previous'!B120 -> CH4 | C48: ='DB_Aspen simulation_previous'!C120 -> kmol/hr | D48: ='DB_Aspen simulation_previous'!D120 -> 13186.8 | E48: ='DB_Aspen simulation_previous'!E120 -> 0 | F48: ='DB_Aspen simulation_previous'!F120 -> 40695.935 | G48: ='DB_Aspen simulation_previous'!G120 -> 28344.536 | H48: ='DB_Aspen simulation_previous'!H120 -> 0.43146133 | I48: ='DB_Aspen simulation_previous'!I120 -> 1.1295021e-14 | ... N48: ='DB_Aspen simulation_previous'!N120 -> 0 | R48: 13186.8 | S48: 0 | T48: 40695.935 | U48: 28344.536 | V48: 0.43146133 | W48: 1.1295021e-14 | X48: 0.20312417 | Y48: 7.4918187e-06 | Z48: 622.64269 | AA48: 0 | AB48: 0
B49: ='DB_Aspen simulation_previous'!B121 -> C2H6 | C49: ='DB_Aspen simulation_previous'!C121 -> kmol/hr | D49: ='DB_Aspen simulation_previous'!D121 -> 0 | E49: ='DB_Aspen simulation_previous'!E121 -> 0 | F49: ='DB_Aspen simulation_previous'!F121 -> 3.8575921 | G49: ='DB_Aspen simulation_previous'!G121 -> 126.35705 | H49: ='DB_Aspen simulation_previous'!H121 -> 9.4418223e-13 | I49: ='DB_Aspen simulation_previous'!I121 -> 122.44253 | ... N49: ='DB_Aspen simulation_previous'!N121 -> 0 | R49: 0 | S49: 0 | T49: 3.8575921 | U49: 126.35705 | V49: 9.4418223e-13 | W49: 122.44253 | X49: 0.0063581651 | Y49: 0.00010754155 | Z49: 0.00027909048 | AA49: 0 | AB49: 0
B50: ='DB_Aspen simulation_previous'!B122 -> C2H4 | C50: ='DB_Aspen simulation_previous'!C122 -> kmol/hr | D50: ='DB_Aspen simulation_previous'!D122 -> 0 | E50: ='DB_Aspen simulation_previous'!E122 -> 0 | F50: ='DB_Aspen simulation_previous'!F122 -> 338.47624 | G50: ='DB_Aspen simulation_previous'!G122 -> 2511.5369 | H50: ='DB_Aspen simulation_previous'!H122 -> 2167.0134 | I50: ='DB_Aspen simulation_previous'!I122 -> 2.1691536 | ... N50: ='DB_Aspen simulation_previous'!N122 -> 0 | R50: 0 | S50: 0 | T50: 338.47624 | U50: 2511.5369 | V50: 2167.0134 | W50: 2.1691536 | X50: 0.084735456 | Y50: 0.0003748476 | Z50: 0.15035486 | AA50: 0 | AB50: 0
B51: ='DB_Aspen simulation_previous'!B123 -> C2H2 | C51: ='DB_Aspen simulation_previous'!C123 -> kmol/hr | D51: ='DB_Aspen simulation_previous'!D123 -> 0 | E51: ='DB_Aspen simulation_previous'!E123 -> 0 | F51: ='DB_Aspen simulation_previous'!F123 -> 66.628656 | G51: ='DB_Aspen simulation_previous'!G123 -> 2624.5266 | H51: ='DB_Aspen simulation_previous'!H123 -> 2.6065817 | I51: ='DB_Aspen simulation_previous'!I123 -> 2554.23 | ... N51: ='DB_Aspen simulation_previous'!N123 -> 0 | R51: 0 | S51: 0 | T51: 66.628656 | U51: 2624.5266 | V51: 2.6065817 | W51: 2554.23 | X51: 0.14815622 | Y51: 0.0046312008 | Z51: 0.0032250312 | AA51: 0 | AB51: 0
B52: ='DB_Aspen simulation_previous'!B124 -> C3-C5 | C52: ='DB_Aspen simulation_previous'!C124 -> kmol/hr | D52: ='DB_Aspen simulation_previous'!D124 -> 0 | E52: ='DB_Aspen simulation_previous'!E124 -> 0 | F52: ='DB_Aspen simulation_previous'!F124 -> 0 | G52: ='DB_Aspen simulation_previous'!G124 -> 0 | H52: ='DB_Aspen simulation_previous'!H124 -> 0 | I52: ='DB_Aspen simulation_previous'!I124 -> 0 | ... N52: ='DB_Aspen simulation_previous'!N124 -> 0 | R52: 0 | S52: 0 | T52: 0 | U52: 0 | V52: 0 | W52: 0 | X52: 0 | Y52: 0 | Z52: 0 | AA52: 0 | AB52: 0
B53: ='DB_Aspen simulation_previous'!B125 -> BEN | C53: ='DB_Aspen simulation_previous'!C125 -> kmol/hr | D53: ='DB_Aspen simulation_previous'!D125 -> 0 | E53: ='DB_Aspen simulation_previous'!E125 -> 0 | F53: ='DB_Aspen simulation_previous'!F125 -> 3.5999699e-07 | G53: ='DB_Aspen simulation_previous'!G125 -> 153.98553 | H53: ='DB_Aspen simulation_previous'!H125 -> 5.2571404e-239 | I53: ='DB_Aspen simulation_previous'!I125 -> 7.0036464 | ... N53: ='DB_Aspen simulation_previous'!N125 -> 0 | R53: 0 | S53: 0 | T53: 3.5999699e-07 | U53: 153.98553 | V53: 5.2571404e-239 | W53: 7.0036464 | X53: 2.2504466 | Y53: 144.71826 | Z53: 6.6589645e-18 | AA53: 0 | AB53: 0
B54: ='DB_Aspen simulation_previous'!B126 -> NAP | C54: ='DB_Aspen simulation_previous'!C126 -> kmol/hr | D54: ='DB_Aspen simulation_previous'!D126 -> 0 | E54: ='DB_Aspen simulation_previous'!E126 -> 0 | F54: ='DB_Aspen simulation_previous'!F126 -> 1.8118093e-56 | G54: ='DB_Aspen simulation_previous'!G126 -> 33.068929 | H54: ='DB_Aspen simulation_previous'!H126 -> 0 | I54: ='DB_Aspen simulation_previous'!I126 -> 7.4870779e-06 | ... N54: ='DB_Aspen simulation_previous'!N126 -> 0 | R54: 0 | S54: 0 | T54: 1.8118093e-56 | U54: 33.068929 | V54: 0 | W54: 7.4870779e-06 | X54: 32.199125 | Y54: 0.86903727 | Z54: 0 | AA54: 0 | AB54: 0
B55: ='DB_Aspen simulation_previous'!B127 -> C | C55: ='DB_Aspen simulation_previous'!C127 -> kmol/hr | D55: ='DB_Aspen simulation_previous'!D127 -> 0 | E55: ='DB_Aspen simulation_previous'!E127 -> 0 | F55: ='DB_Aspen simulation_previous'!F127 -> 0 | G55: ='DB_Aspen simulation_previous'!G127 -> 0 | H55: ='DB_Aspen simulation_previous'!H127 -> 0 | I55: ='DB_Aspen simulation_previous'!I127 -> 0 | ... N55: ='DB_Aspen simulation_previous'!N127 -> 1392.0025 | R55: 0 | S55: 0 | T55: 0 | U55: 0 | V55: 0 | W55: 0 | X55: 0 | Y55: 0 | Z55: 0 | AA55: 0 | AB55: 1392.0025
B56: ='DB_Aspen simulation_previous'!B128 -> WATER | C56: ='DB_Aspen simulation_previous'!C128 -> kmol/hr | D56: ='DB_Aspen simulation_previous'!D128 -> 0 | E56: ='DB_Aspen simulation_previous'!E128 -> 0 | F56: ='DB_Aspen simulation_previous'!F128 -> 0 | G56: ='DB_Aspen simulation_previous'!G128 -> 0 | H56: ='DB_Aspen simulation_previous'!H128 -> 0 | I56: ='DB_Aspen simulation_previous'!I128 -> 0 | ... N56: ='DB_Aspen simulation_previous'!N128 -> 0 | R56: 0 | S56: 0 | T56: 0 | U56: 0 | V56: 0 | W56: 0 | X56: 0 | Y56: 0 | Z56: 0 | AA56: 0 | AB56: 0
B57: ='DB_Aspen simulation_previous'!B129 -> O2 | C57: ='DB_Aspen simulation_previous'!C129 -> kmol/hr | D57: ='DB_Aspen simulation_previous'!D129 -> 0 | E57: ='DB_Aspen simulation_previous'!E129 -> 1400 | F57: ='DB_Aspen simulation_previous'!F129 -> 0 | G57: ='DB_Aspen simulation_previous'!G129 -> 0 | H57: ='DB_Aspen simulation_previous'!H129 -> 0 | I57: ='DB_Aspen simulation_previous'!I129 -> 0 | ... N57: ='DB_Aspen simulation_previous'!N129 -> 0 | R57: 0 | S57: 1400 | T57: 0 | U57: 0 | V57: 0 | W57: 0 | X57: 0 | Y57: 0 | Z57: 0 | AA57: 7.9975 | AB57: 0
B58: ='DB_Aspen simulation_previous'!B130 -> CO2 | C58: ='DB_Aspen simulation_previous'!C130 -> kmol/hr | D58: ='DB_Aspen simulation_previous'!D130 -> 0 | E58: ='DB_Aspen simulation_previous'!E130 -> 0 | F58: ='DB_Aspen simulation_previous'!F130 -> 0 | G58: ='DB_Aspen simulation_previous'!G130 -> 0 | H58: ='DB_Aspen simulation_previous'!H130 -> 0 | I58: ='DB_Aspen simulation_previous'!I130 -> 0 | ... N58: ='DB_Aspen simulation_previous'!N130 -> 0 | R58: 0 | S58: 0 | T58: 0 | U58: 0 | V58: 0 | W58: 0 | X58: 0 | Y58: 0 | Z58: 0 | AA58: 1392.0025 | AB58: 0
B59: ='DB_Aspen simulation_previous'!B144 -> Mass Flows | C59: ='DB_Aspen simulation_previous'!C144 -> kg/hr | D59: ='DB_Aspen simulation_previous'!D144 -> 211552.67 | E59: ='DB_Aspen simulation_previous'!E144 -> 44798.32 | F59: ='DB_Aspen simulation_previous'!F144 -> 1028831.7 | G59: ='DB_Aspen simulation_previous'!G144 -> 1012012.5 | H59: ='DB_Aspen simulation_previous'!H144 -> 60867.667 | I59: ='DB_Aspen simulation_previous'!I144 -> 70796.472 | ... N59: ='DB_Aspen simulation_previous'!N144 -> 16719.342
B60: ='DB_Aspen simulation_previous'!B145 -> H2 | C60: ='DB_Aspen simulation_previous'!C145 -> kg/hr | D60: ='DB_Aspen simulation_previous'!D145 -> 0 | E60: ='DB_Aspen simulation_previous'!E145 -> 0 | F60: ='DB_Aspen simulation_previous'!F145 -> 364610.22 | G60: ='DB_Aspen simulation_previous'!G145 -> 398426.26 | H60: ='DB_Aspen simulation_previous'!H145 -> 2.1245063e-09 | I60: ='DB_Aspen simulation_previous'!I145 -> 4.3749578e-39 | ... N60: ='DB_Aspen simulation_previous'!N145 -> 0
B61: ='DB_Aspen simulation_previous'!B146 -> CH4 | C61: ='DB_Aspen simulation_previous'!C146 -> kg/hr | D61: ='DB_Aspen simulation_previous'!D146 -> 211552.67 | E61: ='DB_Aspen simulation_previous'!E146 -> 0 | F61: ='DB_Aspen simulation_previous'!F146 -> 652875.12 | G61: ='DB_Aspen simulation_previous'!G146 -> 454724.6 | H61: ='DB_Aspen simulation_previous'!H146 -> 6.9218306 | I61: ='DB_Aspen simulation_previous'!I146 -> 1.8120331e-13 | ... N61: ='DB_Aspen simulation_previous'!N146 -> 0
B62: ='DB_Aspen simulation_previous'!B147 -> C2H6 | C62: ='DB_Aspen simulation_previous'!C147 -> kg/hr | D62: ='DB_Aspen simulation_previous'!D147 -> 0 | E62: ='DB_Aspen simulation_previous'!E147 -> 0 | F62: ='DB_Aspen simulation_previous'!F147 -> 115.9964 | G62: ='DB_Aspen simulation_previous'!G147 -> 3799.5111 | H62: ='DB_Aspen simulation_previous'!H147 -> 2.839122e-11 | I62: ='DB_Aspen simulation_previous'!I147 -> 3681.8027 | ... N62: ='DB_Aspen simulation_previous'!N147 -> 0
B63: ='DB_Aspen simulation_previous'!B148 -> C2H4 | C63: ='DB_Aspen simulation_previous'!C148 -> kg/hr | D63: ='DB_Aspen simulation_previous'!D148 -> 0 | E63: ='DB_Aspen simulation_previous'!E148 -> 0 | F63: ='DB_Aspen simulation_previous'!F148 -> 9495.5312 | G63: ='DB_Aspen simulation_previous'!G148 -> 70458.053 | H63: ='DB_Aspen simulation_previous'!H148 -> 60792.875 | I63: ='DB_Aspen simulation_previous'!I148 -> 60.852914 | ... N63: ='DB_Aspen simulation_previous'!N148 -> 0
B64: ='DB_Aspen simulation_previous'!B149 -> C2H2 | C64: ='DB_Aspen simulation_previous'!C149 -> kg/hr | D64: ='DB_Aspen simulation_previous'!D149 -> 0 | E64: ='DB_Aspen simulation_previous'!E149 -> 0 | F64: ='DB_Aspen simulation_previous'!F149 -> 1734.869 | G64: ='DB_Aspen simulation_previous'!G149 -> 68337.109 | H64: ='DB_Aspen simulation_previous'!H149 -> 67.869862 | I64: ='DB_Aspen simulation_previous'!I149 -> 66506.735 | ... N64: ='DB_Aspen simulation_previous'!N149 -> 0
...

Sheet 5. Sensitivity
B2: -20%: | C2: Case 4_FH | D2: Case 4_efurnace | E2: Case 5_FH | F2: Case 5_efurnace | H2: +20%: | I2: Case 4_FH | J2: Case 4_efurnace | K2: Case 5_FH | L2: Case 5_efurnace | O2: -20% | P2: Based | Q2: +20%
C3: 0.011398261 | D3: 0.72559845 | E3: 0.63378365 | F3: 1.756879 | I3: 0.011398261 | J3: 0.72559845 | K3: 0.63378365 | L3: 1.756879
B4: Natural gas price ($/MMBTU) | C4: -0.091276695 | D4: 0.6547902 | E4: 0.52282631 | F4: 1.690355 | H4: Natural gas price ($/MMBTU) | I4: 0.11407322 | J4: 0.7964067 | K4: 0.744741 | L4: 1.8234031 | N4: Natural gas price ($/MMBTU) | O4: =P4*0.8 -> 2.616 | P4: 3.27 | Q4: =P4*1.2 -> 3.924
B5: By-product H2 price ($/kg) | C5: 0.20951934 | D5: 0.92371953 | E5: 0.8131482 | F5: 1.9362436 | H5: By-product H2 price ($/kg) | I5: -0.18672282 | J5: 0.52747737 | K5: 0.45441911 | L5: 1.5775145 | N5: By-product H2 price ($/kg) | O5: =P5*0.8 -> 3.16 | P5: 3.95 | Q5: =P5*1.2 -> 4.74
B6: Grid electricity ($/kWh) | C6: -0.033692491 | D6: 0.72559845 | E6: 0.5324055 | F6: 1.756879 | H6: Grid electricity ($/kWh) | I6: 0.056489013 | J6: 0.72559845 | K6: 0.73516181 | L6: 1.756879 | N6: Grid electricity ($/kWh) | O6: =P6*0.8 -> 0.0552 | P6: 0.069 | Q6: =P6*1.2 -> 0.0828
B7: Renewable electricity ($/kWh) | C7: 0.011398261 | D7: 0.47269003 | E7: 0.63378365 | F7: 1.3457684 | H7: Renewable electricity ($/kWh) | I7: 0.011398261 | J7: 0.97850688 | K7: 0.63378365 | L7: 2.1679897 | N7: Renewable electricity ($/kWh) | O7: =P7*0.8 -> 0.0768 | P7: 0.096 | Q7: =P7*1.2 -> 0.1152
B8: Interest rate (%) | C8: -0.02132741 | D8: 0.69503012 | E8: 0.59391008 | F8: 1.7172206 | H8: Interest rate (%) | I8: 0.045846189 | J8: 0.75777551 | K8: 0.67575566 | L8: 1.7986246 | N8: Interest rate (%) | O8: =P8*0.8 -> 0.064 | P8: 0.08 | Q8: =P8*1.2 -> 0.096
B12: =C2 -> Case 4_FH | C12: Based UPC | D12: =C3 -> 0.011398261
C13: Value | E13: Increase
C14: -20% | D14: +20% | E14: -20% | F14: +20%
B15: Natural gas price ($/MMBTU) | C15: =C4 -> -0.091276695 | D15: =I4 -> 0.11407322 | E15: =(C15-$D$12)/$D$12 -> -9.0079491 | F15: =(D15-$D$12)/$D$12 -> 9.0079491
B16: By-product H2 price ($/kg) | C16: =C5 -> 0.20951934 | D16: =I5 -> -0.18672282 | E16: =(C16-$D$12)/$D$12 -> 17.381694 | F16: =(D16-$D$12)/$D$12 -> -17.381694
B17: Grid electricity ($/kWh) | C17: =C6 -> -0.033692491 | D17: =I6 -> 0.056489013 | E17: =(C17-$D$12)/$D$12 -> -3.9559325 | F17: =(D17-$D$12)/$D$12 -> 3.9559325
B18: Renewable electricity ($/kWh) | C18: =C7 -> 0.011398261 | D18: =I7 -> 0.011398261 | E18: =(C18-$D$12)/$D$12 -> 0 | F18: =(D18-$D$12)/$D$12 -> 0
B19: Interest rate (%) | C19: =C8 -> -0.02132741 | D19: =I8 -> 0.045846189 | E19: =(C19-$D$12)/$D$12 -> -2.8711108 | F19: =(D19-$D$12)/$D$12 -> 3.022209
B21: =D2 -> Case 4_efurnace | C21: Based UPC | D21: =D3 -> 0.72559845
C22: Value | E22: Increase
C23: -20% | D23: +20% | E23: -20% | F23: +20%
B24: Natural gas price ($/MMBTU) | C24: =D4 -> 0.6547902 | D24: =J4 -> 0.7964067 | E24: =(C24-$D$21)/$D$21 -> -0.097585999 | F24: =(D24-$D$21)/$D$21 -> 0.097585999
B25: By-product H2 price ($/kg) | C25: =D5 -> 0.92371953 | D25: =J5 -> 0.52747737 | E25: =(C25-$D$21)/$D$21 -> 0.27304507 | F25: =(D25-$D$21)/$D$21 -> -0.27304507
B26: Grid electricity ($/kWh) | C26: =D6 -> 0.72559845 | D26: =J6 -> 0.72559845 | E26: =(C26-$D$21)/$D$21 -> 0 | F26: =(D26-$D$21)/$D$21 -> 0
B27: Renewable electricity ($/kWh) | C27: =D7 -> 0.47269003 | D27: =J7 -> 0.97850688 | E27: =(C27-$D$21)/$D$21 -> -0.3485515 | F27: =(D27-$D$21)/$D$21 -> 0.3485515
B28: Interest rate (%) | C28: =D8 -> 0.69503012 | D28: =J8 -> 0.75777551 | E28: =(C28-$D$21)/$D$21 -> -0.042128444 | F28: =(D28-$D$21)/$D$21 -> 0.044345542
B30: =E2 -> Case 5_FH | C30: Based UPC | D30: =E3 -> 0.63378365
C31: Value | E31: Increase
C32: -20% | D32: +20% | E32: -20% | F32: +20%
B33: Natural gas price ($/MMBTU) | C33: =E4 -> 0.52282631 | D33: =K4 -> 0.744741 | E33: =(C33-$D$30)/$D$30 -> -0.17507133 | F33: =(D33-$D$30)/$D$30 -> 0.17507133
B34: By-product H2 price ($/kg) | C34: =E5 -> 0.8131482 | D34: =K5 -> 0.45441911 | E34: =(C34-$D$30)/$D$30 -> 0.28300595 | F34: =(D34-$D$30)/$D$30 -> -0.28300595
B35: Grid electricity ($/kWh) | C35: =E6 -> 0.5324055 | D35: =K6 -> 0.73516181 | E35: =(C35-$D$30)/$D$30 -> -0.15995703 | F35: =(D35-$D$30)/$D$30 -> 0.15995703
B36: Renewable electricity ($/kWh) | C36: =E7 -> 0.63378365 | D36: =K7 -> 0.63378365 | E36: =(C36-$D$30)/$D$30 -> 0 | F36: =(D36-$D$30)/$D$30 -> 0
B37: Interest rate (%) | C37: =E8 -> 0.59391008 | D37: =K8 -> 0.67575566 | E37: =(C37-$D$30)/$D$30 -> -0.062913541 | F37: =(D37-$D$30)/$D$30 -> 0.066224498
B39: =F2 -> Case 5_efurnace | C39: Based UPC | D39: =F3 -> 1.756879
C40: Value | E40: Increase
C41: -20% | D41: +20% | E41: -20% | F41: +20%
B42: Natural gas price ($/MMBTU) | C42: =F4 -> 1.690355 | D42: =L4 -> 1.8234031 | E42: =(C42-$D$39)/$D$39 -> -0.037864893 | F42: =(D42-$D$39)/$D$39 -> 0.037864893
B43: By-product H2 price ($/kg) | C43: =F5 -> 1.9362436 | D43: =L5 -> 1.5775145 | E43: =(C43-$D$39)/$D$39 -> 0.10209271 | F43: =(D43-$D$39)/$D$39 -> -0.10209271
B44: Grid electricity ($/kWh) | C44: =F6 -> 1.756879 | D44: =L6 -> 1.756879 | E44: =(C44-$D$39)/$D$39 -> 0 | F44: =(D44-$D$39)/$D$39 -> 0
B45: Renewable electricity ($/kWh) | C45: =F7 -> 1.3457684 | D45: =L7 -> 2.1679897 | E45: =(C45-$D$39)/$D$39 -> -0.23400053 | F45: =(D45-$D$39)/$D$39 -> 0.23400053
B46: Interest rate (%) | C46: =F8 -> 1.7172206 | D46: =L8 -> 1.7986246 | E46: =(C46-$D$39)/$D$39 -> -0.02257324 | F46: =(D46-$D$39)/$D$39 -> 0.023761204

Sheet 5. HEN_Worksheet_Case4
C2: Heat exchanger | E2: Cold stream | F2: Cold T in | H2: Cold T out | J2: Hot stream | K2: Hot T in | M2: Hot T out | O2: Load (kJ/h) | P2: Load (MW) | Q2: Area (m2)
B3: 1 | C3: E-110 | E3: 39_To_42 | F3: -152.58127 | H3: 35 | I3: 1 | J3: 5_To_10 | K3: 1230 | M3: 697.77413 | N3: FALSE | O3: 77245002 | P3: =O3/3600000 -> 21.456945 | Q3: 2209.505 | S3: 1195 | T3: 850.3554
B4: 2 | C4: E-111 | E4: 3_To_4 | F4: 33.11567 | H4: 708.07038 | I4: 1 | J4: 5_To_10 | K4: 1230 | M4: 697.77413 | N4: FALSE | O4: 2.7153907e+09 | P4: =O4/3600000 -> 754.27521 | Q4: 231868.91 | S4: 521.92962 | T4: 664.65846
B5: 3 | C5: E-112 | E5: 31_To_35 | F5: 15 | H5: 35 | I5: 1 | J5: 5_To_10 | K5: 697.77413 | M5: 666.15607 | N5: FALSE | O5: 41005773 | P5: =O5/3600000 -> 11.390492 | Q5: 524.36286 | S5: 662.77413 | T5: 651.15607
B6: 4 | C6: E-113 | E6: 45_To_46 | F6: -124.97704 | H6: 35 | I6: 1 | J6: 5_To_10 | K6: 697.77413 | M6: 666.15607 | N6: FALSE | O6: 1.0591177e+08 | P6: =O6/3600000 -> 29.419937 | Q6: 1517.8128 | S6: 662.77413 | T6: 791.13311
B7: 5 | C7: E-114 | E7: 31_To_35 | F7: 1.663465 | H7: 15 | I7: 1 | J7: 14_To_15 | K7: 35 | M7: 27.114621 | N7: 1 | O7: 27343746 | P7: =O7/3600000 -> 7.5954851 | Q7: 2627.52 | S7: 20 | T7: 25.451156
B8: 6 | C8: E-115 | E8: CW | F8: 20 | H8: 25 | I8: FALSE | J8: 5_To_10 | K8: 666.15607 | M8: 95.001737 | N8: 1 | O8: 2.391974e+09 | P8: =O8/3600000 -> 664.43723 | Q8: 63656.534 | S8: 641.15607 | T8: 75.001737
B9: 7 | C9: E-116 | E9: 31_To_35 | F9: -119.47366 | H9: 1.663465 | I9: 1 | J9: 5_To_10 | K9: 95.001737 | M9: 30 | N9: 1 | O9: 2.4836607e+08 | P9: =O9/3600000 -> 68.990576 | Q9: 18828.978 | S9: 93.338272 | T9: 149.47366
B10: 8 | C10: E-117 | E10: To Reboiler@T3_TO_28-C2C5 | F10: -87.391501 | H10: -82.18093 | I10: FALSE | J10: 22_To_24 | K10: -60 | M10: -75.406232 | N10: 1 | O10: 52482156 | P10: =O10/3600000 -> 14.578377 | Q10: 3627.0799 | S10: 22.18093 | T10: 11.985269
B11: 9 | C11: E-118 | E11: 31_To_35 | F11: -154.96705 | H11: -119.47366 | I11: 1 | J11: To Condenser@T3_TO_27-ETHYL | K11: -104.12595 | M11: -104.19312 | N11: 1 | O11: 72771688 | P11: =O11/3600000 -> 20.214358 | Q11: 2547.8667 | S11: 15.347708 | T11: 50.773925
B12: 10 | C12: E-119 | E12: To Reboiler@T2_TO_26-C2+ | F12: -56.348231 | H12: -51.280823 | I12: 1 | J12: 17_To_18 | K12: 20 | M12: -28.567041 | N12: 1 | O12: 1.753865e+08 | P12: =O12/3600000 -> 48.718471 | Q12: 3506.0192 | S12: 71.280823 | T12: 27.781191
B13: 11 | C13: E-120 | E13: To Reboiler@T3_TO_28-C2C5 | F13: -87.391501 | H13: -82.18093 | I13: FALSE | J13: V3_heat | K13: -31.127413 | M13: -44.433369 | N13: 1 | O13: 45654056 | P13: =O13/3600000 -> 12.681682 | Q13: 1544.7447 | S13: 51.053517 | T13: 42.958132
B14: 12 | C14: E-121 | E14: CRYOTEMP | F14: -269.24253 | H14: -269 | I14: FALSE | J14: 29_To_30 | K14: -140 | M14: -159.13216 | N14: 1 | O14: 1.1640974e+08 | P14: =O14/3600000 -> 32.336038 | Q14: 452.97963 | S14: 129 | T14: 110.11037
B15: 13 | C15: E-122 | E15: CRYOTEMP | F15: -269.24253 | H15: -269 | I15: FALSE | J15: To Condenser@T1_TO_21 | K15: 38.387637 | M15: 0.89491272 | N15: 1 | O15: 323821.28 | P15: =O15/3600000 -> 0.089950357 | Q15: 1.0619544 | S15: 307.38764 | T15: 270.13744
B16: 14 | C16: E-123 | E16: CRYOTEMP | F16: -269.24253 | H16: -269 | I16: FALSE | J16: To Condenser@T2_TO_45Duplicate | K16: -124.73484 | M16: -124.97704 | N16: 1 | O16: 18896309 | P16: =O16/3600000 -> 5.2489746 | Q16: 67.131286 | S16: 144.26516 | T16: 144.26549
B17: 15 | C17: E-124 | E17: To Reboiler@T1_TO_20-BEN | F17: 250.52967 | H17: 251.23443 | I17: 1 | J17: FIRED | K17: 2000 | M17: 830 | N17: FALSE | O17: 18534905 | P17: =O17/3600000 -> 5.1485847 | Q17: 44.84747 | S17: 1748.7656 | T17: 579.47033
B18: 16 | C18: E-125 | E18: 31_To_35 | F18: -167 | H18: -154.96705 | I18: 1 | J18: 14_To_15 | K18: 27.114621 | M18: 20 | N18: 1 | O18: 24671025 | P18: =O18/3600000 -> 6.8530624 | Q18: 280.39569 | S18: 182.08167 | T18: 187
B19: 17 | C19: E-126 | E19: CRYOTEMP | F19: -270 | H19: -269.24253 | I19: FALSE | J19: V5_heat | K19: -159.13216 | M19: -167 | N19: 1 | O19: 37516725 | P19: =O19/3600000 -> 10.421313 | Q19: 564.50129 | S19: 110.11037 | T19: 103
B20: 18 | C20: E-127 | E20: CRYOTEMP | F20: -270 | H20: -269.24253 | I20: FALSE | J20: V4_heat | K20: -103.3156 | M20: -140 | N20: 1 | O20: 2.8346503e+08 | P20: =O20/3600000 -> 78.740286 | Q20: 3086.0353 | S20: 165.92693 | T20: 130
B21: 19 | C21: E-128 | E21: CRYOTEMP | F21: -270 | H21: -269.24253 | I21: FALSE | J21: 22_To_24 | K21: -75.406232 | M21: -103.3156 | N21: 1 | O21: 1.0261631e+08 | P21: =O21/3600000 -> 28.50453 | Q21: 628.58755 | S21: 193.8363 | T21: 166.6844
B22: 20 | C22: E-129 | E22: V1_heat | F22: 34.865664 | H22: 35 | I22: 1 | J22: LPS | K22: 125 | M22: 124.05067 | N22: FALSE | O22: 467559.65 | P22: =O22/3600000 -> 0.12987768 | Q22: 7.4899246 | S22: 90 | T22: 89.185005
B23: 21 | C23: E-130 | E23: To Reboiler@T3_TO_28-C2C5 | F23: -88.318585 | H23: -87.391501 | I23: FALSE | J23: 17_To_18 | K23: -28.567041 | M23: -31.141817 | N23: 1 | O23: 9298096.2 | P23: =O23/3600000 -> 2.5828045 | Q23: 135.92547 | S23: 58.82446 | T23: 57.176767
B24: 22 | C24: E-131 | E24: 39_To_42 | F24: -169.27894 | H24: -152.58127 | I24: 1 | J24: To Condenser@T3_TO_27-ETHYL | K24: -104.19312 | M24: -106.01723 | N24: 1 | O24: 1.0315914e+08 | P24: =O24/3600000 -> 28.655317 | Q24: 296.12329 | S24: 48.388147 | T24: 63.261706
B25: 23 | C25: E-132 | E25: To Reboiler@T3_TO_28-C2C5 | F25: -88.318585 | H25: -87.391501 | I25: FALSE | J25: V3_heat | K25: -44.433369 | M25: -60 | N25: 1 | O25: 53410658 | P25: =O25/3600000 -> 14.836294 | Q25: 2179.8082 | S25: 42.958132 | T25: 28.318585
B26: 24 | C26: E-133 | E26: V1_heat | F26: 34.858494 | H26: 34.865664 | I26: 1 | J26: LPS | K26: 124.05067 | M26: 124 | N26: FALSE | O26: 24954.91 | P26: =O26/3600000 -> 0.0069319196 | Q26: 0.40167801 | S26: 89.185005 | T26: 89.141506
A29: Heating requirement | C29: Heat exchanger | E29: Cold stream | F29: Cold T in | H29: Cold T out | J29: Hot stream | K29: Hot T in | M29: Hot T out | O29: Load (kJ/h) | P29: Load (MW) | Q29: Area (m2) | W29: Heating requirement | Y29: Cooling requirement
A30: Cat | B30: 1 | C30: =C4 -> E-111 | D30: =D4 -> 0 | E30: =E4 -> 3_To_4 | F30: =F4 -> 33.11567 | G30: =G4 -> 0 | H30: =H4 -> 708.07038 | I30: =I4 -> 1 | J30: =J4 -> 5_To_10 | ... Q30: =Q4 -> 231868.91 | S30: =S4 -> 521.92962 | T30: =T4 -> 664.65846 | W30: Before | X30: After | Y30: Before | Z30: After
V31: Catalytic conversion | W31: =P30 -> 754.27521 | X31: 0 | Y31: =SUM(P53:P58) -> 1549.9704 | Z31: =P57 -> 664.43723
A32: Compress & G/L sep | B32: 2 | C32: =C17 -> E-124 | D32: =D17 -> 0 | E32: =E17 -> To Reboiler@T1_TO_20-BEN | F32: =F17 -> 250.52967 | G32: =G17 -> 0 | H32: =H17 -> 251.23443 | I32: =I17 -> 1 | J32: =J17 -> FIRED | ... Q32: =Q17 -> 44.84747 | S32: =S17 -> 1748.7656 | T32: =T17 -> 579.47033 | V32: Compression and G/L separation | W32: =SUM(P32:P35) -> 20.121688 | X32: =P32+P34+P35 -> 5.2853943 | Y32: =SUM(P60:P68) -> 113.1851 | Z32: =P64+P65 -> 5.338925
B33: 3 | C33: =C25 -> E-132 | D33: =D25 -> 0 | E33: =E25 -> To Reboiler@T3_TO_28-C2C5 | F33: =F25 -> -88.318585 | G33: =G25 -> 0 | H33: =H25 -> -87.391501 | I33: =I25 -> FALSE | J33: =J25 -> V3_heat | ... Q33: =Q25 -> 2179.8082 | S33: =S25 -> 42.958132 | T33: =T25 -> 28.318585 | V33: Coldbox and cryogenic separation | W33: =SUM(P37:P49) -> 287.9738 | X33: 0 | Y33: =SUM(P70:P75) -> 197.36731 | Z33: =SUM(P71:P74) -> 148.49764
B34: 4 | C34: =C26 -> E-133 | D34: =D26 -> 0 | E34: =E26 -> V1_heat | F34: =F26 -> 34.858494 | G34: =G26 -> 0 | H34: =H26 -> 34.865664 | I34: =I26 -> 1 | J34: =J26 -> LPS | ... Q34: =Q26 -> 0.40167801 | S34: =S26 -> 89.185005 | T34: =T26 -> 89.141506 | V34: SUM | W34: =SUM(W31:W33) -> 1062.3707 | X34: =SUM(X31:X33) -> 5.2853943 | Y34: =SUM(Y31:Y33) -> 1860.5228 | Z34: =SUM(Z31:Z33) -> 818.27379
B35: 5 | C35: =C22 -> E-129 | D35: =D22 -> 0 | E35: =E22 -> V1_heat | F35: =F22 -> 34.865664 | G35: =G22 -> 0 | H35: =H22 -> 35 | I35: =I22 -> 1 | J35: =J22 -> LPS | ... Q35: =Q22 -> 7.4899246 | S35: =S22 -> 90 | T35: =T22 -> 89.185005
A37: Cryogenic separation and recovery | B37: 6 | C37: =C3 -> E-110 | D37: =D3 -> 0 | E37: =E3 -> 39_To_42 | F37: =F3 -> -152.58127 | G37: =G3 -> 0 | H37: =H3 -> 35 | I37: =I3 -> 1 | J37: =J3 -> 5_To_10 | ... Q37: =Q3 -> 2209.505 | S37: =S3 -> 1195 | T37: =T3 -> 850.3554
B38: 7 | C38: =C5 -> E-112 | D38: =D5 -> 0 | E38: =E5 -> 31_To_35 | F38: =F5 -> 15 | G38: =G5 -> 0 | H38: =H5 -> 35 | I38: =I5 -> 1 | J38: =J5 -> 5_To_10 | ... Q38: =Q5 -> 524.36286 | S38: =S5 -> 662.77413 | T38: =T5 -> 651.15607
B39: 8 | C39: =C6 -> E-113 | D39: =D6 -> 0 | E39: =E6 -> 45_To_46 | F39: =F6 -> -124.97704 | G39: =G6 -> 0 | H39: =H6 -> 35 | I39: =I6 -> 1 | J39: =J6 -> 5_To_10 | ... Q39: =Q6 -> 1517.8128 | S39: =S6 -> 662.77413 | T39: =T6 -> 791.13311
B40: 9 | C40: =C7 -> E-114 | D40: =D7 -> 0 | E40: =E7 -> 31_To_35 | F40: =F7 -> 1.663465 | G40: =G7 -> 0 | H40: =H7 -> 15 | I40: =I7 -> 1 | J40: =J7 -> 14_To_15 | ... Q40: =Q7 -> 2627.52 | S40: =S7 -> 20 | T40: =T7 -> 25.451156
B41: 10 | C41: =C9 -> E-116 | D41: =D9 -> 0 | E41: =E9 -> 31_To_35 | F41: =F9 -> -119.47366 | G41: =G9 -> 0 | H41: =H9 -> 1.663465 | I41: =I9 -> 1 | J41: =J9 -> 5_To_10 | ... Q41: =Q9 -> 18828.978 | S41: =S9 -> 93.338272 | T41: =T9 -> 149.47366
B42: 11 | C42: =C10 -> E-117 | D42: =D10 -> 0 | E42: =E10 -> To Reboiler@T3_TO_28-C2C5 | F42: =F10 -> -87.391501 | G42: =G10 -> 0 | H42: =H10 -> -82.18093 | I42: =I10 -> FALSE | J42: =J10 -> 22_To_24 | ... Q42: =Q10 -> 3627.0799 | S42: =S10 -> 22.18093 | T42: =T10 -> 11.985269
B43: 12 | C43: =C11 -> E-118 | D43: =D11 -> 0 | E43: =E11 -> 31_To_35 | F43: =F11 -> -154.96705 | G43: =G11 -> 0 | H43: =H11 -> -119.47366 | I43: =I11 -> 1 | J43: =J11 -> To Condenser@T3_TO_27-ETHYL | ... Q43: =Q11 -> 2547.8667 | S43: =S11 -> 15.347708 | T43: =T11 -> 50.773925
B44: 13 | C44: =C12 -> E-119 | D44: =D12 -> 0 | E44: =E12 -> To Reboiler@T2_TO_26-C2+ | F44: =F12 -> -56.348231 | G44: =G12 -> 0 | H44: =H12 -> -51.280823 | I44: =I12 -> 1 | J44: =J12 -> 17_To_18 | ... Q44: =Q12 -> 3506.0192 | S44: =S12 -> 71.280823 | T44: =T12 -> 27.781191
...

Sheet Previous_Economic Analysis
A1: 1. Assumption and parameters
B3: ASSUMPTION AND PARAMETERS | H3: PURCHASED EQUIPMENT COST ($)
B4: Location | F4: North America | H4: Reactor (R1+E1)_1245MW | L4: =100.38*10^6*(1246/500)^0.67 -> 1.850693e+08 | M4: https://doi.org/10.1016/j.joule.2018.01.001
B5: System Cost Base Date | F5: 1Q 16 | H5: Flash tank
B6: Project Type | F6: Grass roots/Clear field | H6: V1 | L6: ='Previous_Equipment cost'!E48 -> 1476700
B7: Plant lifetime (y) | F7: 30 | H7: V2 | L7: ='Previous_Equipment cost'!E53 -> 1090800
B8: Annual operating hours (h) | F8: 8000 | H8: V3 | L8: ='Previous_Equipment cost'!E51 -> 949500
B9: Depreciation method | F9: Straight line | H9: V4 | L9: ='Previous_Equipment cost'!E63 -> 444700
B10: Interest rate (%) | F10: 8 | H10: V5 | L10: ='Previous_Equipment cost'!E32 -> 443200
B11: Tax rate (%) | F11: 35 | H11: Columns
H12: T1 | L12: =SUM('Previous_Equipment cost'!E20:E26) -> 125300
B13: FACTOR FOR TCI | H13: T2 | L13: =SUM('Previous_Equipment cost'!E54:E60) -> 1031800
B14: Total capital investment cost (TCI) | F14: =SUBTOTAL(9,F15:F29) -> 5.04 | H14: T3 | L14: =SUM('Previous_Equipment cost'!E37:E43) -> 3547200
B15: Direct plan cost | F15: =SUBTOTAL(9,F16:F23) -> 3.6 | H15: Heat exchanger, heater, cooler
B16: Purchased equipment (PE) | F16: 1 | H16: E2 | L16: ='Previous_Equipment cost'!E19 -> 12850900
B17: Equipment setting | F17: 0.47 | H17: E3 | L17: ='Previous_Equipment cost'!E27 -> 4429400
B18: Instrumentation and control | F18: 0.36 | H18: E4 | L18: ='Previous_Equipment cost'!E47 -> 8613900
B19: Piping | F19: 0.68 | H19: HX1 | L19: =(541.7/280)*101.3*28232^0.65*(0.8+0)*1 -> 122541.25 | M19: Douglas_KoltsegFuggvenyek estimated for HE
B20: Electrical installation | F20: 0.11 | H20: HX2 | L20: =541.7/323.8*398*(1375/1)^0.65*(1+0.52)*1 -> 110944.4
B21: Building and building services | F21: 0.18 | H21: HX3 | L21: ='Previous_Equipment cost'!E44 -> 1865400
B22: Yard improvements | F22: 0.1 | H22: HX4 | L22: ='Previous_Equipment cost'!E62 -> 409400
B23: Services facilities | F23: 0.7 | H23: HX5 | L23: ='Previous_Equipment cost'!$E$61 -> 475200
B24: Indirect plant cost | F24: =SUBTOTAL(9,F25:F29) -> 1.44 | H24: HX6 | L24: ='Previous_Equipment cost'!E29 -> 801700
B25: Engineering | F25: 0.33 | H25: Total | L25: =SUM(L4:L24) -> 2.2385788e+08
B26: Construction expenses | F26: 0.41
B27: Legal expenses | F27: 0.04
B28: Contractor's fee | F28: 0.22
B29: Contingency | F29: 0.44
A31: 2. Calculation of Production Costs and Revenue
B33: ECONOMIC CALCULATION | H33: Variable operating cost ($/year) | U33: lb | V33: kg | AE33: Value (MM$)
B34: Total capital investment cost (TCI) ($) | F34: =F14*$L$25 -> 1.1282437e+09 | K34: Weight factor | M34: Unit price | O34: Total amount (year) | Q34: Original ($) | R34: Changed | S34: % | U34: 1 | V34: 0.45359237 | AD34: Total capital investment cost (TCI) | AE34: =F34/10^6 -> 1128.2437 | AF34: 1128.2437
B35: Direct plan cost | F35: =F15*$L$25 -> 8.0588838e+08 | H35: Raw materials | Q35: =SUBTOTAL(9,Q36) -> 3.0306628e+08 | R35: =SUBTOTAL(9,R36) -> 3.0306628e+08 | S35: =(R35-Q35)/Q35 -> 0 | AD35: Direct plan cost | AE35: =F35/10^6 -> 805.88838 | AF35: 805.88838
B36: Purchased equipment (PE) | F36: =F16*$L$25 -> 2.2385788e+08 | H36: CH4 | K36: 1 | M36: 3.27 | N36: $/MMBTU | O36: ='Previous_Technical performance'!D72/28.263682*8000 -> 92680819 | P36: MMBTU | Q36: =O36*M36 -> 3.0306628e+08 | R36: =Q36*K36 -> 3.0306628e+08 | S36: =(R36-Q36)/Q36 -> 0 | T36: 1 MMBTU = 28.263682 m3 NG | AD36: Purchased equipment (PE) | AE36: =F36/10^6 -> 223.85788 | AF36: 223.85788
B37: Equipment setting | F37: =F17*$L$25 -> 1.0521321e+08 | H37: Utility | Q37: =SUBTOTAL(9,Q38:Q44) -> 9.3721732e+08 | R37: =SUBTOTAL(9,R38:R44) -> 9.3721732e+08 | S37: =(R37-Q37)/Q37 -> 0 | AD37: Equipment setting | AE37: =F37/10^6 -> 105.21321 | AF37: 105.21321
B38: Instrumentation and control | F38: =F18*$L$25 -> 80588838 | H38: O2 | K38: 1 | M38: 40 | N38: $/ton | O38: ='Previous_Technical performance'!E59/1000*8000 -> 358386.56 | P38: ton | Q38: =O38*M38 -> 14335462 | R38: =Q38*K38 -> 14335462 | S38: =(R38-Q38)/Q38 -> 0 | U38: =Q38/10^6 -> 14.335462 | AD38: Instrumentation and control | AE38: =F38/10^6 -> 80.588838 | AF38: 80.588838
B39: Piping | F39: =F19*$L$25 -> 1.5222336e+08 | H39: Refrigeration | K39: 1 | M39: 8.9e-06 | N39: $/kJ | O39: ='DB_Aspen simulation_previous'!D176*8760 -> 9.6950683e+09 | P39: MJ | Q39: =O39*1000*M39 -> 86286108 | R39: =Q39*K39 -> 86286108 | S39: =(R39-Q39)/Q39 -> 0 | U39: =Q39/10^6 -> 86.286108 | AD39: Piping | AE39: =F39/10^6 -> 152.22336 | AF39: 152.22336
B40: Electrical installation | F40: =F20*$L$25 -> 24624367 | H40: Electricity | K40: 1 | M40: 0.069 | N40: $/kWh | O40: ='DB_Aspen simulation_previous'!F177*8760 -> 8388696888 | P40: kWh | Q40: =O40*M40 -> 5.7882009e+08 | R40: =Q40*K40 -> 5.7882009e+08 | S40: =(R40-Q40)/Q40 -> 0 | U40: =Q40/10^6 -> 578.82009 | AD40: Electrical installation | AE40: =F40/10^6 -> 24.624367 | AF40: 24.624367
B41: Building and building services | F41: =F21*$L$25 -> 40294419 | H41: Cooling water | K41: 1 | M41: 0.03 | N41: $/ton | O41: ='DB_Aspen simulation_previous'!F178/1000*8760 -> 3396138120 | P41: ton | Q41: =O41*M41 -> 1.0188414e+08 | R41: =Q41*K41 -> 1.0188414e+08 | S41: =(R41-Q41)/Q41 -> 0 | U41: =Q41/10^6 -> 101.88414 | AD41: Building and building services | AE41: =F41/10^6 -> 40.294419 | AF41: 40.294419
B42: Yard improvements | F42: =F22*$L$25 -> 22385788 | H42: High pressure steam | K42: 1 | M42: 14.5 | N42: $/ton | O42: ='DB_Aspen simulation_previous'!F180/1000*8760 -> 39471.947 | P42: ton | Q42: =O42*M42 -> 572343.23 | R42: =Q42*K42 -> 572343.23 | S42: =(R42-Q42)/Q42 -> 0 | U42: =Q42/10^6 -> 0.57234323 | AD42: Yard improvements | AE42: =F42/10^6 -> 22.385788 | AF42: 22.385788
B43: Services facilities | F43: =F23*$L$25 -> 1.5670052e+08 | H43: Low pressure steam | K43: 1 | M43: 10.5 | N43: $/ton | O43: ='DB_Aspen simulation_previous'!F181/1000*8760 -> 1147958.6 | P43: ton | Q43: =O43*M43 -> 12053565 | R43: =Q43*K43 -> 12053565 | S43: =(R43-Q43)/Q43 -> 0 | U43: =Q43/10^6 -> 12.053565 | AD43: Services facilities | AE43: =F43/10^6 -> 156.70052 | AF43: 156.70052
...

Sheet Previous_Equipment cost
A1: EQUIP.ICS (Equipment)
J2: CASE 1
