Workbook

Sheet 1. DB_Experiment_VER1
C1: SABIC | D1: KRICT (5.8%) | E1: KRICT (10%) | F1: KRICT (20%) | G1: KRICT (30%) | H1: KRICT (업데이트 실험결과)
A2: Reference | C2: PCT/US2018/012064
C3: US 7,919,431 B2
A4: Preheating | J4: lb | K4: g
A5: Temp (oC) | C5: 500 | D5: - | J5: 1 | K5: 453.592
A7: CH4 pyrolysis | J7: 43.5
A8: Temp (oC) | C8: 2500 | D8: 1114 | E8: 1114 | F8: 1114 | G8: 1114 | H8: 1230
A9: CH4 feed (lb/h) | C9: 43.5
A10: CH4 feed (g/h) | C10: =C9*K5 -> 19731.252
A11: CH4 feed (ml/min) | D11: 20 | E11: 20 | F11: 20 | G11: 20 | H11: 14.4
A12: CH4 feed (mol/h) | C12: =C10/16 -> 1233.2033 | D12: =D11*60/22400 -> 0.053571429 | E12: =E11*60/22400 -> 0.053571429 | F12: =F11*60/22400 -> 0.053571429 | G12: =G11*60/22400 -> 0.053571429 | H12: =H11*60/22400 -> 0.038571429
A13: H2 feed (ml/min) | D13: 60 | E13: 60 | F13: 60 | G13: 60 | H13: 64
A14: H2 feed (mol/h) | D14: =D13*60/22400 -> 0.16071429 | E14: =E13*60/22400 -> 0.16071429 | F14: =F13*60/22400 -> 0.16071429 | G14: =G13*60/22400 -> 0.16071429 | H14: =H13*60/22400 -> 0.17142857 | I14: H2/CH4 | J14: =H14/H12 -> 4.4444444
A15: CH4 fuel (lb/h) | C15: 55.6
A16: CH4 fuel (g/h) | C16: =C15*K5 -> 25219.715
A17: CH4 fuel (mol/h) | C17: =C16/16 -> 1576.2322
A18: Pure O2 (lb/h) | C18: 182.8
A19: O2 fuel (g/h) | C19: =C18*K5 -> 82916.618
A20: O2 fuel (mol/h) | C20: =C19/32 -> 2591.1443
A21: Duty (Mbtu/h) | C21: 1114
A22: O2 stoichometry (%) | C22: 88.4
A27: Methane conversion (%) | C27: 51.3 | D27: 5.8 | E27: 10 | F27: 20 | G27: 30 | H27: 30.353963
A29: Product composition (C%)
A30: C2H6 | D30: 5.5 | E30: 5.5 | F30: 5.5 | G30: 5.5 | H30: 1.9832376
A31: C2H4 | D31: 60.3 | E31: 60.3 | F31: 60.3 | G31: 60.3 | H31: 35.180966
A32: C2H2 | D32: 2.9 | E32: 2.9 | F32: 2.9 | G32: 2.9 | H32: 41.411786
A33: C3-C5 | D33: 1.3 | E33: 1.3 | F33: 1.3 | G33: 1.3 | H33: 0
A34: Benzene | D34: 4.3 | E34: 4.3 | F34: 4.3 | G34: 4.3 | H34: 7.4789878
A35: Naphthalene | D35: 25.6 | E35: 25.6 | F35: 25.6 | G35: 25.6 | H35: 2.6768978
A36: Coke | H36: 11.268125
A37: Total | D37: =SUM(D30:D35) -> 99.9 | E37: =SUM(E30:E35) -> 99.9 | F37: =SUM(F30:F35) -> 99.9 | G37: =SUM(G30:G35) -> 99.9 | H37: =SUM(H30:H36) -> 100
L38: -253 | M38: Hydrogen in hydrocarbon | N38: 1 CASE | O38: 2 CASE | P38: 3 CASE | Q38: 4 CASE | R38: KRICT (업데이트 실험결과)
A39: Product composition (mol/h) (1) | L39: -164 | M39: CH4 | N39: =D12*D27/100*2 -> 0.0062142857 | O39: =E12*E27/100*2 -> 0.010714286 | P39: =F12*F27/100*2 -> 0.021428571 | Q39: =G12*G27/100*2 -> 0.032142857 | R39: =H12*H27/100*2 -> 0.023415914 | S39: =Q39/$Q$48*100 -> 48.056122
A40: H2 | C40: =$C$42*C54/$C$56 -> 1544.3952 | D40: =D14+N47 -> 0.1643282 | E40: =E14+O47 -> 0.1688282 | F40: =F14+P47 -> 0.17954249 | G40: =G14+Q47 -> 0.19025678 | H40: =H14+R47 -> 0.1873898 | I40: =H40*10000 -> 1873.898 | L40: -89 | M40: C2H6 | N40: =D43*3 -> 0.00025633929 | O40: =E43*3 -> 0.00025633929 | P40: =F43*3 -> 0.00025633929 | Q40: =G43*3 -> 0.00025633929 | R40: =H43*3 -> 0.0003482949 | S40: =Q40/$Q$48*100 -> 0.38324757
A41: CO2 | C41: =$C$42*C55/$C$56 -> 859.26123 | I41: =H41*10000 -> 0 | L41: -104 | M41: C2H4 | N41: =D44*2 -> 0.0018736071 | O41: =E44*2 -> 0.0018736071 | P41: =F44*2 -> 0.0018736071 | Q41: =G44*2 -> 0.0018736071 | R41: =H44*2 -> 0.0041189724 | S41: =Q41/$Q$48*100 -> 2.8011913
A42: CH4 | C42: =C12*C27/100 -> 632.63327 | D42: =D12*(100-D27)/100 -> 0.050464286 | E42: =E12*(100-E27)/100 -> 0.048214286 | F42: =F12*(100-F27)/100 -> 0.042857143 | G42: =G12*(100-G27)/100 -> 0.0375 | H42: =H12*(100-H27)/100 -> 0.026863472 | I42: =H42*10000 -> 268.63472 | L42: -84 | M42: C2H2 | N42: =D45*1 -> 4.5053571e-05 | O42: =E45*1 -> 4.5053571e-05 | P42: =F45*1 -> 4.5053571e-05 | Q42: =G45*1 -> 4.5053571e-05 | R42: =H45*1 -> 0.002424237 | S42: =Q42/$Q$48*100 -> 0.067358664
A43: C2H6 | D43: =($D$12-$D$42)*D30/100/2 -> 8.5446429e-05 | E43: =($D$12-$D$42)*E30/100/2 -> 8.5446429e-05 | F43: =($D$12-$D$42)*F30/100/2 -> 8.5446429e-05 | G43: =($D$12-$D$42)*G30/100/2 -> 8.5446429e-05 | H43: =($H$12-$H$42)*H30/100/2 -> 0.0001160983 | I43: =H43*10000 -> 1.160983 | L43: -84 | M43: C3-C5 | N43: =D46*3 -> 4.0392857e-05 | O43: =E46*3 -> 4.0392857e-05 | P43: =F46*3 -> 4.0392857e-05 | Q43: =G46*3 -> 4.0392857e-05 | R43: =H46*3 -> 0 | S43: =Q43/$Q$48*100 -> 0.060390526
A44: C2H4 | C44: =$C$42*C58/$C$56 -> 21.000274 | D44: =($D$12-$D$42)*D31/100/2 -> 0.00093680357 | E44: =($D$12-$D$42)*E31/100/2 -> 0.00093680357 | F44: =($D$12-$D$42)*F31/100/2 -> 0.00093680357 | G44: =($D$12-$D$42)*G31/100/2 -> 0.00093680357 | H44: =($H$12-$H$42)*H31/100/2 -> 0.0020594862 | I44: =H44*10000 -> 20.594862 | L44: -47 -> 36 | M44: Benzene | N44: =D47*3 -> 6.6803571e-05 | O44: =E47*3 -> 6.6803571e-05 | P44: =F47*3 -> 6.6803571e-05 | Q44: =G47*3 -> 6.6803571e-05 | R44: =H47*3 -> 0.00043781834 | S44: =Q44/$Q$48*100 -> 0.09987664
A45: C2H2 | C45: =$C$42*C59/$C$56 -> 200.37762 | D45: =($D$12-$D$42)*D32/100/2 -> 4.5053571e-05 | E45: =($D$12-$D$42)*E32/100/2 -> 4.5053571e-05 | F45: =($D$12-$D$42)*F32/100/2 -> 4.5053571e-05 | G45: =($D$12-$D$42)*G32/100/2 -> 4.5053571e-05 | H45: =($H$12-$H$42)*H32/100/2 -> 0.002424237 | I45: =H45*10000 -> 24.24237 | L45: 80 | M45: Naphthalene | N45: =D48*4 -> 0.00031817143 | O45: =E48*4 -> 0.00031817143 | P45: =F48*4 -> 0.00031817143 | Q45: =G48*4 -> 0.00031817143 | R45: =H48*4 -> 0.00012536402 | S45: =Q45/$Q$48*100 -> 0.47569153
A46: C3-C5 | D46: =($D$12-$D$42)*D33/100/3 -> 1.3464286e-05 | E46: =($D$12-$D$42)*E33/100/3 -> 1.3464286e-05 | F46: =($D$12-$D$42)*F33/100/3 -> 1.3464286e-05 | G46: =($D$12-$D$42)*G33/100/3 -> 1.3464286e-05 | H46: =($H$12-$H$42)*H33/100/3 -> 0 | I46: =H46*10000 -> 0 | L46: 218 | M46: H2 | N46: =SUM(N40:N45) -> 0.0026003679 | O46: =SUM(O40:O45) -> 0.0026003679 | P46: =SUM(P40:P45) -> 0.0026003679 | Q46: =SUM(Q40:Q45) -> 0.0026003679 | R46: =SUM(R40:R45) -> 0.0074546866 | S46: =(Q46+Q47)/Q48*100 -> 48.056122
...

Sheet 2. Aspen_stream info
A1: Case 1: Feed H2/CH4=4.56
C37: Units | D37: 1 | E37: 2 | F37: 3 | G37: 4 | H37: 5 | I37: 6 | J37: 7 | K37: 8 | L37: 9 | M37: 10 | N37: 11 | O37: 12 | P37: 13 | Q37: 14 | R37: 15 | S37: 16 | T37: 17 | U37: 18 | AK37: 33 | AL37: 34 | AM37: 35 | AN37: 36 | AO37: 37-H2PRO | AP37: 38 | AQ37: 39 | AR37: 40 | AS37: 41 | AT37: 42 | AU37: 43 | AV37: 44 | AW37: 44-RECY | AX37: 45 | AY37: 45D | AZ37: 46 | BA37: 47 | BB37: 48 | BC37: DECOKING | BD37: EXHAUTED | BE37: FUELGAS | BF37: O2 | BG37: S2 | BH37: S3 | BI37: S4 | BJ37: S5 | BK37: S6 | BL37: S7 | BM37: S8 | BN37: S14 | BO37: S17 | BQ37: 49 | BR37: 50 | BS37: 51-H20 | BT37: 52 | BU37: 53-CO2 | BV37: 54
B38: Temperature | C38: C | D38: 30 | E38: 670.68848 | F38: 30 | G38: 30 | H38: 35 | I38: 0.014251963 | J38: -60 | K38: -116.46255 | L38: -140 | M38: -140 | N38: -125.13065 | O38: 35 | P38: 250.11226 | Q38: -86.520964 | R38: -104.08476 | S38: 30 | T38: 73.417094 | U38: 435.97057
B39: Pressure | C39: bar | D39: 1.013 | E39: 1.013 | F39: 1.013 | G39: 1.013 | H39: 20.000001 | I39: 30 | J39: 30 | K39: 30 | L39: 30 | M39: 30 | N39: 10 | O39: 20 | P39: 30 | Q39: 1.013 | R39: 1.013 | S39: 30 | T39: 1 | U39: 100
B40: Mass Flows | C40: kg/hr | D40: 211552.67 | E40: 1205811.6 | F40: 170758.44 | G40: 694833.86 | H40: 1201147.2 | I40: 1201851.9 | J40: 14202.474 | K40: 1186011.2 | L40: 242525.68 | M40: 943485.52 | N40: 82436.757 | O40: 1639.5145 | P40: 13579.035 | Q40: 14988.357 | R40: 145100.57 | S40: 29499.336 | T40: 259541.22 | U40: 462488.73
B41: Mole Flows | C41: kmol/hr | D41: 13186.8 | E41: 262299.21 | F41: 10643.957 | G41: 21714.472 | H41: 268714.41 | I41: 268723.02 | J41: 192.14321 | K41: 268548.3 | L41: 10927.346 | M41: 257620.96 | N41: 5311.429 | O41: 13.281328 | P41: 173.26753 | Q41: 443.95684 | R41: 5171.9601 | S41: 13684.157 | T41: =SUM(T42:T58) -> 4661.1285 | U41: =SUM(U42:U58) -> 12258.962
B42: H2 | C42: kmol/hr | D42: 0 | E42: 214570.8 | F42: 0 | G42: 0 | H42: 228104.44 | I42: 228104.54 | J42: 1.2403407 | K42: 228122.29 | L42: 198.16268 | M42: 227924.13 | N42: 198.16268 | O42: 0.08087674 | P42: 0.00054280782 | Q42: 4.9527945e-128 | R42: 3.1212174e-08 | S42: 13547.725 | T42: 0 | U42: 0
B43: CH4 | C43: kmol/hr | D43: 13186.8 | E43: 47100.907 | F43: 10643.957 | G43: 0 | H43: 34177.99 | I43: 34178.154 | J43: 3.9210295 | K43: 34179.988 | L43: 5113.2663 | M43: 29066.722 | N43: 5112.7352 | O43: 0.077206607 | P43: 0.004607 | Q43: 2.1145211e-55 | R43: 0.53114204 | S43: 136.43213 | T43: 0 | U43: 0
B44: C2H6 | C44: kmol/hr | D44: 0 | E44: 14.990365 | F44: 0 | G44: 0 | H44: 404.47038 | I44: 404.48959 | J44: 0.85583746 | K44: 404.48513 | L44: 389.41961 | M44: 15.065518 | N44: 0.00011652648 | O44: 0.0061573979 | P44: 0.0047991323 | Q44: 382.46465 | R44: 6.9548468 | S44: 0 | T44: 0 | U44: 0
B45: C2H4 | C45: kmol/hr | D45: 0 | E45: 612.50984 | F45: 0 | G45: 0 | H45: 5784.909 | I45: 5785.0832 | J45: 6.9300903 | K45: 5785.2169 | L45: 5170.1747 | M45: 615.0422 | N45: 0.53102555 | O45: 0.059518262 | P45: 0.027274211 | Q45: 5.169639 | R45: 5164.4741 | S45: 0 | T45: 0 | U45: 0
B46: C2H2 | C46: kmol/hr | D46: 0 | E46: 0 | F46: 0 | G46: 0 | H46: 0 | I46: 0 | J46: 0 | K46: 0 | L46: 0 | M46: 0 | N46: 0 | O46: 0 | P46: 0 | Q46: 0 | R46: 0 | S46: 0 | T46: 0 | U46: 0
B47: C3-C5 | C47: kmol/hr | D47: 0 | E47: 0 | F47: 0 | G47: 0 | H47: 0 | I47: 0 | J47: 0 | K47: 0 | L47: 0 | M47: 0 | N47: 0 | O47: 0 | P47: 0 | Q47: 0 | R47: 0 | S47: 0 | T47: 0 | U47: 0
B48: BEN | C48: kmol/hr | D48: 0 | E48: 1.2479361e-06 | F48: 0 | G48: 0 | H48: 179.03478 | I48: 185.78118 | J48: 170.24839 | K48: 8.2673701 | L48: 8.2673688 | M48: 1.2542071e-06 | N48: 1.6725117e-28 | O48: 0.71855832 | P48: 170.05968 | Q48: 8.2673689 | R48: 4.5597692e-184 | S48: 0 | T48: 0 | U48: 0
B49: TOL | C49: kmol/hr | D49: 0 | E49: 4.8846085e-36 | F49: 0 | G49: 0 | H49: 2.0798313 | I49: 2.3257184 | J49: 2.0357775 | K49: 0.01952693 | L49: 0.01952693 | M49: 2.0840603e-10 | N49: 4.9091543e-36 | O49: 0.02469848 | P49: 2.0357316 | Q49: 0.01952693 | R49: 5.0573522e-256 | S49: 0 | T49: 0 | U49: 0
B50: NAP | C50: kmol/hr | D50: 0 | E50: 7.428528e-62 | F50: 0 | G50: 0 | H50: 12.900267 | I50: 14.027632 | J50: 0.59417385 | K50: 5.1250835e-06 | L50: 5.1250835e-06 | M50: 1.8140352e-19 | N50: 7.4658573e-62 | O50: 12.307157 | P50: 0.59417385 | Q50: 5.1250835e-06 | R50: 0 | S50: 0 | T50: 0 | U50: 0
B51: C | C51: kmol/hr | D51: 0 | E51: 0 | F51: 0 | G51: 0 | H51: 0 | I51: 0 | J51: 0 | K51: 0 | L51: 0 | M51: 0 | N51: 0 | O51: 0 | P51: 0 | Q51: 0 | R51: 0 | S51: 0 | T51: 0 | U51: 0
B52: WATER | C52: kmol/hr | D52: 0 | E52: 0 | F52: 0 | G52: 0 | H52: 0 | I52: 0 | J52: 0 | K52: 0 | L52: 0 | M52: 0 | N52: 0 | O52: 0 | P52: 0 | Q52: 0 | R52: 0 | S52: 0 | T52: 2172.1047 | U52: 208.95196
B53: O2 | C53: kmol/hr | D53: 0 | E53: 0 | F53: 0 | G53: 21713.672 | H53: 0 | I53: 0 | J53: 0 | K53: 0 | L53: 0 | M53: 0 | N53: 0 | O53: 0 | P53: 0 | Q53: 0 | R53: 0 | S53: 0 | T53: 616.33614 | U53: 0.092282654
... B58: MEA | C58: kmol/hr | D58: 0 | E58: 0 | F58: 0 | G58: 0 | H58: 0 | I58: 0 | J58: 0 | K58: 0 | L58: 0 | M58: 0 | N58: 0 | O58: 0 | P58: 0 | Q58: 0 | R58: 0 | S58: 0 | T58: 0.98631149 | U58: 8.7063481e-14
A134: Case 2: Feed H2/CH4=3.44
C174: Units | D174: 1 | E174: 2 | F174: 3 | G174: 4 | H174: 5 | I174: 6 | J174: 7 | K174: 8 | L174: 9 | M174: 10 | N174: 11 | O174: 12 | P174: 13 | Q174: 14 | R174: 15 | S174: 16 | T174: 17 | U174: 18 | CD174: 49 | CE174: 50 | CF174: 51-H20 | CG174: 52 | CH174: 53-CO2 | CI174: 54
B175: Temperature | C175: C | D175: 30 | E175: -17.405867 | F175: 30 | G175: 30 | H175: 35 | I175: 5 | J175: -60 | K175: -115.5874 | L175: -140 | M175: -140 | N175: -121.63486 | O175: 35 | P175: 236.73034 | Q175: -86.622042 | R175: -104.10278 | S175: 30 | T175: 70.357541 | U175: 454.88512
B176: Pressure | C176: bar | D176: 1.013 | E176: 1.013 | F176: 1.013 | G176: 1.013 | H176: 12.000001 | I176: 30 | J176: 30 | K176: 30 | L176: 30 | M176: 30 | N176: 10 | O176: 12.000001 | P176: 30 | Q176: 1.013 | R176: 1.013 | S176: 30 | T176: 1 | U176: 100 | CD176: B1 | CE176: B3 | CF176: B3 | CH176: REG | CI176: ABS
B177: Mass Flows | C177: kg/hr | D177: 211552.67 | E177: 973264.55 | F177: 128009.95 | G177: 520891.41 | H177: 961723.57 | I177: 960620.51 | J177: 19335.514 | K177: 939991.21 | L177: 245831.07 | M177: 694160.14 | N177: 100891.48 | O177: 2743.1846 | P177: 18915.199 | Q177: 11496.629 | R177: 133442.96 | S177: 31440.49 | T177: 259541.22 | U177: 462488.73 | CD177: B2 | CE177: ABS | CG177: P-2
B178: Mole Flows | C178: kmol/hr | D178: 13186.8 | E178: 186082.31 | F178: 7979.2973 | G178: 16278.566 | H178: 192970.26 | I178: 192950.63 | J178: 264.93512 | K178: 192687.73 | L178: 11530.333 | M178: 181157.4 | N178: 6437.4849 | O178: 22.201642 | P178: 245.65464 | Q178: 336.18263 | R178: 4756.6655 | S178: 14585.699 | T178: 9566.4568 | U178: 10699.893 | CD178: CONVEN | CE178: CONVEN | CF178: CONVEN | CG178: CONVEN | CH178: CONVEN | CI178: CONVEN
B179: H2 | C179: kmol/hr | D179: 0 | E179: 143846.48 | F179: 0 | G179: 0 | H179: 158295.65 | I179: 158283.72 | J179: 1.6946171 | K179: 158283.57 | L179: 225.06672 | M179: 158058.51 | N179: 225.06672 | O179: 0.078875336 | P179: 2.033959e-10 | Q179: 3.9036005e-131 | R179: 5.9429166e-11 | S179: 14440.444 | T179: 0 | U179: 0
B180: CH4 | C180: kmol/hr | D180: 13186.8 | E180: 41761.88 | F180: 7979.2973 | G180: 0 | H180: 28837.904 | I180: 28835.837 | J180: 6.4321517 | K180: 28835.625 | L180: 6148.6807 | M180: 22686.944 | N180: 6148.0433 | O180: 0.092530506 | P180: 2.5752669e-05 | Q180: 1.9701817e-55 | R180: 0.63736686 | S180: 145.25476 | T180: 0 | U180: 0
B181: C2H6 | C181: kmol/hr | D181: 0 | E181: 7.5975226 | F181: 0 | G181: 0 | H181: 290.25931 | I181: 290.24834 | J181: 1.1842817 | K181: 289.4443 | L181: 281.92498 | M181: 7.5193134 | N181: 0.11636206 | O181: 0.006375187 | P181: 0.78624235 | Q181: 277.71083 | R181: 4.0977882 | S181: 0 | T181: 0 | U181: 0
B182: C2H4 | C182: kmol/hr | D182: 0 | E182: 466.35309 | F182: 0 | G182: 0 | H182: 5232.0225 | I182: 5231.7179 | J182: 12.122394 | K182: 5230.1415 | L182: 4825.7118 | M182: 404.42971 | N182: 64.258479 | O182: 0.077267539 | P182: 1.3668024 | Q182: 9.5229459 | R182: 4751.9304 | S182: 0 | T182: 0 | U182: 0 | CD182: Vapor Phase | CE182: Vapor Phase | CF182: Liquid Phase | CG182: Liquid Phase | CH182: Vapor Phase | CI182: Vapor Phase
B183: C2H2 | C183: kmol/hr | D183: 0 | E183: 0 | F183: 0 | G183: 0 | H183: 0 | I183: 0 | J183: 0 | K183: 0 | L183: 0 | M183: 0 | N183: 0 | O183: 0 | P183: 0 | Q183: 0 | R183: 0 | S183: 0 | T183: 0 | U183: 0 | CD183: 751.89471 | CE183: 25 | CF183: 25 | CG183: 40 | CH183: 61.824198 | CI183: 70.664026
B184: C3-C5 | C184: kmol/hr | D184: 0 | E184: 0 | F184: 0 | G184: 0 | H184: 0 | I184: 0 | J184: 0 | K184: 0 | L184: 0 | M184: 0 | N184: 0 | O184: 0 | P184: 0 | Q184: 0 | R184: 0 | S184: 0 | T184: 0 | U184: 0 | CD184: 1.013 | CE184: 1.013 | CF184: 1.013 | CG184: 1.01 | CH184: 1.9 | CI184: 1
B185: BEN | C185: kmol/hr | D185: 0 | E185: 7.4581557e-07 | F185: 0 | G185: 0 | H185: 236.4843 | I185: 243.33751 | J185: 229.06156 | K185: 5.9904154 | L185: 5.9904146 | M185: 7.4956339e-07 | N185: 1.9520816e-19 | O185: 1.4146569 | P185: 229.06155 | Q185: 5.9904146 | R185: 1.6576132e-184 | S185: 0 | T185: 0 | U185: 0 | CD185: 1 | CE185: 1 | CF185: 0 | CG185: 0 | CH185: 1 | CI185: 1
B186: TOL | C186: kmol/hr | D186: 0 | E186: 1.8582774e-10 | F186: 0 | G186: 0 | H186: 3.2521056 | I186: 3.5401487 | J186: 3.17645 | K186: 0.016240968 | L186: 0.016240968 | M186: 1.8676155e-10 | N186: 6.2522786e-26 | O186: 0.059175205 | P186: 3.17645 | Q186: 0.016240968 | R186: 1.9177343e-256 | S186: 0 | T186: 0 | U186: 0 | CD186: 0 | CE186: 0 | CF186: 1 | CG186: 1 | CH186: 0 | CI186: 0
B187: NAP | C187: kmol/hr | D187: 0 | E187: 1.0519083e-45 | F187: 0 | G187: 0 | H187: 20.95804 | I187: 8.4695451 | J187: 0.4958011 | K187: 2.3536126e-06 | L187: 2.3536126e-06 | M187: 8.0835416e-20 | N187: 1.0571943e-45 | O187: 20.461098 | P187: 0.4958011 | Q187: 2.3536126e-06 | R187: 0 | S187: 0 | T187: 0 | U187: 0 | CD187: 0 | CE187: 0 | CF187: 0 | CG187: 0 | CH187: 0 | CI187: 0
B188: C | C188: kmol/hr | D188: 0 | E188: 0 | F188: 0 | G188: 0 | H188: 0 | I188: 0 | J188: 0 | K188: 0 | L188: 0 | M188: 0 | N188: 0 | O188: 0 | P188: 0 | Q188: 0 | R188: 0 | S188: 0 | T188: 0 | U188: 0 | CD188: 1 | CE188: 1 | CF188: 0 | CG188: 0 | CH188: 1 | CI188: 1
B189: WATER | C189: kmol/hr | D189: 0 | E189: 0 | F189: 0 | G189: 0 | H189: 0 | I189: 0 | J189: 0 | K189: 0 | L189: 0 | M189: 0 | N189: 0 | O189: 0 | P189: 0 | Q189: 0 | R189: 0 | S189: 0 | T189: 2695.6741 | U189: 323.31007 | CD189: 0 | CE189: 0 | CF189: 1 | CG189: 1 | CH189: 0 | CI189: 0
B190: O2 | C190: kmol/hr | D190: 0 | E190: 0 | F190: 0 | G190: 16277.766 | H190: 0 | I190: 0 | J190: 0 | K190: 0 | L190: 0 | M190: 0 | N190: 0 | O190: 0 | P190: 0 | Q190: 0 | R190: 0 | S190: 0 | T190: 609.2772 | U190: 0.079046293 | CD190: 0 | CE190: 0 | CF190: 0 | CG190: 0 | CH190: 0 | CI190: 0
B191: CO2 | C191: kmol/hr | D191: 0 | E191: 0 | F191: 0 | G191: 0 | H191: 0 | I191: 0 | J191: 0 | K191: 0 | L191: 0 | M191: 0 | N191: 0 | O191: 0 | P191: 0 | Q191: 0 | R191: 0 | S191: 0 | T191: 1001.677 | U191: 10376.118 | CD191: -53899.406 | CE191: -64255.221 | CF191: -68280.84 | CG191: -67998.295 | CH191: -89477.616 | CI191: -26777.892
B192: CO | C192: kmol/hr | D192: 0 | E192: 0 | F192: 0 | G192: 0 | H192: 0 | I192: 0 | J192: 0 | K192: 0 | L192: 0 | M192: 0 | N192: 0 | O192: 0 | P192: 0 | Q192: 0 | R192: 0 | S192: 0 | T192: 0 | U192: 0 | CD192: -1962.6556 | CE192: -1672.3602 | CF192: -3787.9228 | CG192: -3770.5832 | CH192: -2182.3107 | CI192: -985.58994
B193: N2 | C193: kmol/hr | D193: 0 | E193: 0 | F193: 0 | G193: 0.8 | H193: 0 | I193: 0 | J193: 0 | K193: 0 | L193: 0 | M193: 0 | N193: 0 | O193: 0 | P193: 0 | Q193: 0 | R193: 0 | S193: 0 | T193: 5258.2544 | U193: 0.38496625 | CD193: 7.7189661 | CE193: 1.7570559 | CF193: -38.972575 | CG193: -38.129924 | CH193: -0.14160151 | CI193: 0.27526904
...

Sheet 2-1. Aspen Utility
D2: Case 1 (BASE) | E2: Case 2 (BASE) | F2: Case 3 (BASE) | G2: Case 4 (BASE) | H2: Case 1 (Base w CCS) | I2: Case 2 (Base w CCS) | J2: Case 3 (Base w CCS) | K2: Case 4 (Base w CCS) | L2: Case 1 (E-furnace) | M2: Case 2 (E-furnace) | N2: Case 3 (E-furnace) | O2: Case 4 (E-furnace) | P2: Case 1 (E-furnace w CCS) | Q2: Case 2 (E-furnace w CCS) | R2: Case 3 (E-furnace w CCS) | S2: Case 4 (E-furnace w CCS)
B3: CW | C3: ton/h | D3: =B16 -> 276952 | E3: =L16 -> 194306.1 | F3: =V16 -> 61413.7 | G3: =AF16 -> 129859.3 | H3: =AP16 -> 438472.11 | I3: =BA16 -> 339963.65 | J3: =BL16 -> 180775.04 | K3: =BW16 -> 236478.38 | L3: =CH16 -> 276952 | M3: =CS16 -> 194306.1 | N3: =DD16 -> 61413.7 | O3: =DO16 -> 129859.3 | P3: =DZ16 -> 279960.02 | Q3: =B73 -> 201731.48 | R3: =L73 -> 69354.823 | S3: =V73 -> 142032.07
B4: Grid-Electricity | C4: kWh | D4: =B27 -> 969998 | E4: =L27 -> 705579 | F4: =V27 -> 511184 | G4: =AF27 -> 386920 | H4: =AP27 -> 1029961.3 | I4: =BA27 -> 759523.39 | J4: =BL27 -> 557152.34 | K4: =BW27 -> 429367.09 | L4: =CH27+2418*1000*(8000/8760) -> 3178217.2 | M4: =CS27+1880*1000*(8000/8760) -> 2422474 | N4: =DD27+1541*1000*(8000/8760) -> 1918489.9 | O4: =DO27+1337*1000*(8000/8760) -> 1607924.6 | P4: =DZ27+2418*1000*(8000/8760) -> 3179994.5 | Q4: =B84+1880*1000*(8000/8760) -> 2426821.8 | R4: =L84+1541*1000*(8000/8760) -> 1923163.4 | S4: =V84+1337*1000*(8000/8760) -> 1615304.6
B5: Res-Electricity | C5: kWh
B6: Res-Heat | C6: kWh | BM6: Cal/sec | BN6: -18313676
B7: Fired heat | C7: kWh | D7: =B37 -> 0 | E7: =L37 -> 0 | F7: =V37 -> 0 | G7: =AF37 -> 0 | H7: =AP37 -> 0 | I7: =BA37 -> 0 | J7: =BL37 -> 0 | K7: =BW37 -> 0 | L7: =CH37 -> 0 | M7: =CS37 -> 0 | N7: =DD37 -> 0 | O7: =DO37 -> 0 | P7: =DZ37 -> 0 | Q7: =B94 -> 0 | R7: =L94 -> 0 | S7: =V94 -> 0 | BM7: GJ/hr | BN7: =-BN6*3600/239000000 -> 275.85454 | BP7: kW | BQ7: tonne/hr
B8: HPS (0.78 kWh/kg) | C8: ton/h | D8: =B44 -> 0 | E8: =L44 -> 0 | F8: =V44 -> 0 | G8: =AF44 -> 0 | H8: =AP44 -> 0 | I8: =BA44 -> 0 | J8: =BL44 -> 0 | K8: =BW44 -> 0 | L8: =CH44 -> 0 | M8: =CS44 -> 0 | N8: =DD44 -> 0 | O8: =DO44 -> 0 | P8: =DZ44 -> 0 | Q8: =B101 -> 0 | R8: =L101 -> 0 | S8: =V101 -> 0 | BM8: kW | BN8: =BN7*277.778 -> 76626.321 | BP8: 58333.3 | BQ8: 95.808
B9: LPS (0.75 kWh/kg) | C9: ton/h | D9: =B51 -> 0 | E9: =L51 -> 0 | F9: =V51 -> 0 | G9: =AF51 -> 0 | H9: =AP51 -> 787.09123 | I9: =BA51 -> 649.23816 | J9: =BL51 -> 529.53666 | K9: =BW51 -> 446.3177 | L9: =CH51 -> 0 | M9: =CS51 -> 0 | N9: =DD51 -> 0 | O9: =DO51 -> 0 | P9: =DZ51 -> 22.298386 | Q9: =B108 -> 49.879329 | R9: =L108 -> 50.793452 | S9: =V108 -> 125.85289 | AF9: -18313676 | BM9: tonne/hr | BN9: =BN8*BQ8/BP8 -> 125.85289
B10: Refrigeration | C10: kWh | D10: =B58 -> 238557.95 | E10: =L58 -> 169532.29 | F10: =V58 -> 174006.8 | G10: =AF58 -> 170031.17 | H10: =AP58 -> 238557.95 | I10: =BA58 -> 169532.29 | J10: =BL58 -> 174006.8 | K10: =BW58 -> 170031.17 | L10: =CH58 -> 238557.95 | M10: =CS58 -> 169532.29 | N10: =DD58 -> 174006.8 | O10: =DO58 -> 170031.17 | P10: =DZ58 -> 238557.95 | Q10: =B115 -> 169532.29 | R10: =L115 -> 174006.8 | S10: =V115 -> 170031.17
B11: Enerygy consumption | C11: kWh | D11: =D4+D5+D6+D7+D8*1000*0.78+D9*1000*0.75+D10 -> 1208555.9 | E11: =E4+E5+E6+E7+E8*1000*0.78+E9*1000*0.75+E10 -> 875111.29 | F11: =F4+F5+F6+F7+F8*1000*0.78+F9*1000*0.75+F10 -> 685190.8 | G11: =G4+G5+G6+G7+G8*1000*0.78+G9*1000*0.75+G10 -> 556951.17 | H11: =H4+H5+H6+H7+H8*1000*0.78+H9*1000*0.75+H10 -> 1858837.7 | I11: =I4+I5+I6+I7+I8*1000*0.78+I9*1000*0.75+I10 -> 1415984.3 | J11: =J4+J5+J6+J7+J8*1000*0.78+J9*1000*0.75+J10 -> 1128311.6 | K11: =K4+K5+K6+K7+K8*1000*0.78+K9*1000*0.75+K10 -> 934136.53 | ... S11: =S4+S5+S6+S7+S8*1000*0.78+S9*1000*0.75+S10 -> 1879725.5
AF12: R1 (-3438 MW) | AG12: R1 (-2409 MW) | AH12: R1 (-1944 MW) | AI12: R1 (-1655 MW)
B14: Case 1 (Base) | L14: Case 2 (Base) | V14: Case 3 (Base) | AF14: Case 4 (Base) | AP14: Case 1 (Base w CCS) | BA14: Case 2 (Base w CCS) | BL14: Case 3 (Base w CCS) | BW14: Case 4 (Base w CCS) | CH14: Case 1 (E-furnace) | CS14: Case 2 (E-furnace) | DD14: Case 3 (E-furnace) | DO14: Case 4 (E-furnace) | DZ14: Case 1 (E-furnace w CCS)
B15: CW | D15: Block ID | E15: Block type | F15: Duty | G15: Usage | H15: Cost | I15: CO2 emission rate | L15: CW | N15: Block ID | O15: Block type | P15: Duty | Q15: Usage | R15: Cost | S15: CO2 emission rate | V15: CW | X15: Block ID | Y15: Block type | Z15: Duty | AA15: Usage | AB15: Cost | AC15: CO2 emission rate | AF15: CW | AH15: Block ID | AI15: Block type | AJ15: Duty | AK15: Usage | AL15: Cost | AM15: CO2 emission rate | AP15: CW | AR15: Block ID | AS15: Block type | AT15: Duty | AU15: Usage | AV15: Cost | AW15: CO2 emission rate | BA15: CW | BC15: Block ID | BD15: Block type | BE15: Duty | BF15: Usage | BG15: Cost | BH15: CO2 emission rate | BL15: CW | BN15: Block ID | BO15: Block type | BP15: Duty | BQ15: Usage | BR15: Cost | BS15: CO2 emission rate | BW15: CW | BY15: Block ID | BZ15: Block type | CA15: Duty | CB15: Usage | CC15: Cost | CD15: CO2 emission rate | CH15: CW | CJ15: Block ID | CK15: Block type | CL15: Duty | CM15: Usage | CN15: Cost | CO15: CO2 emission rate | CS15: CW | CU15: Block ID | CV15: Block type | CW15: Duty | CX15: Usage | CY15: Cost | CZ15: CO2 emission rate | DD15: CW | DF15: Block ID | DG15: Block type | DH15: Duty | DI15: Usage | DJ15: Cost | DK15: CO2 emission rate | DO15: CW | DQ15: Block ID | DR15: Block type | DS15: Duty | DT15: Usage | DU15: Cost | DV15: CO2 emission rate | DZ15: CW | EB15: Block ID | EC15: Block type | ED15: Duty | EE15: Usage | EF15: Cost | EG15: CO2 emission rate
B16: =SUM(G17:G25) -> 276952 | C16: ton/h | F16: kW | G16: tonne/hr | H16: $/hr | L16: =SUM(Q17:Q25) -> 194306.1 | M16: ton/h | P16: kW | Q16: tonne/hr | R16: $/hr | V16: =SUM(AA17:AA25) -> 61413.7 | W16: ton/h | Z16: kW | AA16: tonne/hr | AB16: $/hr | AF16: =SUM(AK17:AK25) -> 129859.3 | AG16: ton/h | AJ16: kW | AK16: tonne/hr | AL16: $/hr | AP16: =SUM(AU17:AU25) -> 438472.11 | AQ16: ton/h | AT16: kW | AU16: tonne/hr | AV16: $/hr | BA16: =SUM(BF17:BF25) -> 339963.65 | BB16: ton/h | BE16: kW | BF16: tonne/hr | BG16: $/hr | BL16: =SUM(BQ17:BQ25) -> 180775.04 | BM16: ton/h | BP16: kW | BQ16: tonne/hr | BR16: $/hr | BW16: =SUM(CB17:CB25) -> 236478.38 | BX16: ton/h | CA16: kW | CB16: tonne/hr | CC16: $/hr | CH16: =SUM(CM17:CM25) -> 276952 | CI16: ton/h | CL16: kW | CM16: tonne/hr | CN16: $/hr | CS16: =SUM(CX17:CX25) -> 194306.1 | CT16: ton/h | CW16: kW | CX16: tonne/hr | CY16: $/hr | DD16: =SUM(DI17:DI25) -> 61413.7 | DE16: ton/h | DH16: kW | DI16: tonne/hr | DJ16: $/hr | DO16: =SUM(DT17:DT25) -> 129859.3 | DP16: ton/h | DS16: kW | DT16: tonne/hr | DU16: $/hr | DZ16: =SUM(EE17:EE25) -> 279960.02 | EA16: ton/h | ED16: kW | EE16: tonne/hr | EF16: $/hr
D17: E2 | E17: HEATER | F17: 866610 | G17: 149446 | H17: 661.397 | N17: E2 | O17: HEATER | P17: 648746 | Q17: 111876 | R17: 495.123 | X17: MCOMP1 | Y17: MCOMPR | Z17: 174182 | AA17: 30037.4 | AB17: 132.935 | AH17: E2 | AI17: HEATER | AJ17: 366431 | AK17: 63190.6 | AL17: 279.66 | AR17: E2 | AS17: HEATER | AT17: 866610 | AU17: 149446 | AV17: 661.397 | BC17: E2 | BD17: HEATER | BE17: 648746 | BF17: 111876 | BG17: 495.123 | BN17: MCOMP1 | BO17: MCOMPR | BP17: 174182 | BQ17: 30037.4 | BR17: 132.935 | BY17: E2 | BZ17: HEATER | CA17: 366431 | CB17: 63190.6 | CC17: 279.66 | CJ17: E2 | CK17: HEATER | CL17: 866610 | CM17: 149446 | CN17: 661.397 | CU17: E2 | CV17: HEATER | CW17: 648746 | CX17: 111876 | CY17: 495.123 | DF17: MCOMP1 | DG17: MCOMPR | DH17: 174182 | DI17: 30037.4 | DJ17: 132.935 | DQ17: E2 | DR17: HEATER | DS17: 366431 | DT17: 63190.6 | DU17: 279.66 | EB17: E2 | EC17: HEATER | ED17: 866610 | EE17: 149446 | EF17: 661.397
D18: MCOMP1 | E18: MCOMPR | F18: 676047 | G18: 116584 | H18: 515.959 | N18: MCOMP1 | O18: MCOMPR | P18: 341259 | Q18: 58849.7 | R18: 260.449 | X18: MCOMP2 | Y18: MCOMPR | Z18: 181945 | AA18: 31376.3 | AB18: 138.861 | AH18: MCOMP1 | AI18: MCOMPR | AJ18: 134414 | AK18: 23179.6 | AL18: 102.585 | AR18: MCOMP1 | AS18: MCOMPR | AT18: 676047 | AU18: 116584 | AV18: 515.959 | BC18: MCOMP1 | BD18: MCOMPR | BE18: 341259 | BF18: 58849.7 | BG18: 260.449 | BN18: MCOMP2 | BO18: MCOMPR | BP18: 181945 | BQ18: 31376.3 | BR18: 138.861 | BY18: MCOMP1 | BZ18: MCOMPR | CA18: 134414 | CB18: 23179.6 | CC18: 102.585 | CJ18: MCOMP1 | CK18: MCOMPR | CL18: 676047 | CM18: 116584 | CN18: 515.959 | CU18: MCOMP1 | CV18: MCOMPR | CW18: 341259 | CX18: 58849.7 | CY18: 260.449 | DF18: MCOMP2 | DG18: MCOMPR | DH18: 181945 | DI18: 31376.3 | DJ18: 138.861 | DQ18: MCOMP1 | DR18: MCOMPR | DS18: 134414 | DT18: 23179.6 | DU18: 102.585 | EB18: MCOMP1 | EC18: MCOMPR | ED18: 676047 | EE18: 116584 | EF18: 515.959
D19: MCOMP2 | E19: MCOMPR | F19: 63334.6 | G19: 10922 | H19: 48.337 | N19: MCOMP2 | O19: MCOMPR | P19: 136739 | Q19: 23580.4 | R19: 104.359 | AH19: MCOMP2 | AI19: MCOMPR | AJ19: 252186 | AK19: 43489.1 | AL19: 192.468 | AR19: MCOMP2 | AS19: MCOMPR | AT19: 63334.6 | AU19: 10922 | AV19: 48.337 | BC19: MCOMP2 | BD19: MCOMPR | BE19: 136739 | BF19: 23580.4 | BG19: 104.359 | BY19: MCOMP2 | BZ19: MCOMPR | CA19: 252186 | CB19: 43489.1 | CC19: 192.468 | CJ19: MCOMP2 | CK19: MCOMPR | CL19: 63334.6 | CM19: 10922 | CN19: 48.337 | CU19: MCOMP2 | CV19: MCOMPR | CW19: 136739 | CX19: 23580.4 | CY19: 104.359 | DQ19: MCOMP2 | DR19: MCOMPR | DS19: 252186 | DT19: 43489.1 | DU19: 192.468 | EB19: MCOMP2 | EC19: MCOMPR | ED19: 63334.6 | EE19: 10922 | EF19: 48.337
AR20: B6 | AS20: HEATER | AT20: 19722.8 | AU20: 3397.41 | AV20: 15.0525 | BC20: B5 | BD20: HEATER | BE20: 281103 | BF20: 48422.2 | BG20: 214.538 | BN20: B6 | BO20: HEATER | BP20: 234034 | BQ20: 40314.1 | BR20: 178.614 | BY20: B6 | BZ20: HEATER | CA20: 206973 | CB20: 35652.7 | CC20: 157.962 | EB20: B1 | EC20: HEATER | ED20: 2313.69 | EE20: 398.551 | EF20: 1.7658
AR21: B8 | AS21: HEATER | AT21: 284996 | AU21: 49092.8 | AV21: 217.509 | BC21: B6 | BD21: HEATER | BE21: 16390.9 | BF21: 2823.46 | BG21: 12.5095 | BN21: B7 | BO21: HEATER | BP21: 34853.9 | BQ21: 6003.85 | BR21: 26.6005 | BY21: B7 | BZ21: HEATER | CA21: 13443.2 | CB21: 2315.7 | CC21: 10.2599 | EB21: B5 | EC21: HEATER | ED21: 98.7501 | EE21: 17.0105 | EF21: 0.0753661
AR22: H-1 | AS22: HEATER | AT22: 570966 | AU22: 98353.4 | AV22: 435.761 | BC22: H-1 | BD22: HEATER | BE22: 494811 | BF22: 85235.1 | BG22: 377.64 | BN22: H-1 | BO22: HEATER | BP22: 374000 | BQ22: 64424.5 | BR22: 285.437 | BY22: H-1 | BZ22: HEATER | CA22: 356512 | CB22: 61411.9 | CC22: 272.09 | EB22: H-1 | EC22: HEATER | ED22: 13324.2 | EE22: 2295.21 | EF22: 10.1691
AR23: REG | AS23: RADFRAC | AT23: 61979.9 | AU23: 10676.5 | AV23: 47.3031 | BC23: REG | BD23: RADFRAC | BE23: 53273.6 | BF23: 9176.79 | BG23: 40.6584 | BN23: REG | BO23: RADFRAC | BP23: 50034.8 | BQ23: 8618.89 | BR23: 38.1865 | BY23: REG | BZ23: RADFRAC | CA23: 42022.9 | CB23: 7238.78 | CC23: 32.0719 | EB23: REG | EC23: RADFRAC | ED23: 1725.6 | EE23: 297.249 | EF23: 1.31698
B26: Electricity | D26: Block ID | E26: Block type | F26: Duty | G26: Usage | H26: Cost | I26: CO2 emission rate | L26: Electricity | N26: Block ID | O26: Block type | P26: Duty | Q26: Usage | R26: Cost | S26: CO2 emission rate | V26: Electricity | X26: Block ID | Y26: Block type | Z26: Duty | AA26: Usage | AB26: Cost | AC26: CO2 emission rate | AF26: Electricity | AH26: Block ID | AI26: Block type | AJ26: Duty | AK26: Usage | AL26: Cost | AM26: CO2 emission rate | AP26: Electricity | AR26: Block ID | AS26: Block type | AT26: Duty | AU26: Usage | AV26: Cost | AW26: CO2 emission rate | BA26: Electricity | BC26: Block ID | BD26: Block type | BE26: Duty | BF26: Usage | BG26: Cost | BH26: CO2 emission rate | BL26: Electricity | BN26: Block ID | BO26: Block type | BP26: Duty | BQ26: Usage | BR26: Cost | BS26: CO2 emission rate | BW26: Electricity | BY26: Block ID | BZ26: Block type | CA26: Duty | CB26: Usage | CC26: Cost | CD26: CO2 emission rate | CH26: Electricity | CJ26: Block ID | CK26: Block type | CL26: Duty | CM26: Usage | CN26: Cost | CO26: CO2 emission rate | CS26: Electricity | CU26: Block ID | CV26: Block type | CW26: Duty | CX26: Usage | CY26: Cost | CZ26: CO2 emission rate | DD26: Electricity | DF26: Block ID | DG26: Block type | DH26: Duty | DI26: Usage | DJ26: Cost | DK26: CO2 emission rate | DO26: Electricity | DQ26: Block ID | DR26: Block type | DS26: Duty | DT26: Usage | DU26: Cost | DV26: CO2 emission rate | DZ26: Electricity | EB26: Block ID | EC26: Block type | ED26: Duty | EE26: Usage | EF26: Cost | EG26: CO2 emission rate
B27: =SUM(G28:G35) -> 969998 | C27: kWh | F27: kW | G27: kW | H27: $/hr | I27: kg/hr | L27: =SUM(Q28:Q35) -> 705579 | M27: kWh | P27: kW | Q27: kW | R27: $/hr | S27: kg/hr | V27: =SUM(AA28:AA35) -> 511184 | W27: kWh | Z27: kW | AA27: kW | AB27: $/hr | AC27: kg/hr | AF27: =SUM(AK28:AK35) -> 386920 | AG27: kWh | AJ27: kW | AK27: kW | AL27: $/hr | AM27: kg/hr | AP27: =SUM(AU28:AU35) -> 1029961.3 | AQ27: kWh | AT27: kW | AU27: kW | AV27: $/hr | AW27: kg/hr | BA27: =SUM(BF28:BF35) -> 759523.39 | BB27: kWh | BE27: kW | BF27: kW | BG27: $/hr | BH27: kg/hr | BL27: =SUM(BQ28:BQ35) -> 557152.34 | BM27: kWh | BP27: kW | BQ27: kW | BR27: $/hr | BS27: kg/hr | BW27: =SUM(CB28:CB35) -> 429367.09 | BX27: kWh | CA27: kW | CB27: kW | CC27: $/hr | CD27: kg/hr | CH27: =SUM(CM28:CM35) -> 969998 | CI27: kWh | CL27: kW | CM27: kW | CN27: $/hr | CO27: kg/hr | CS27: =SUM(CX28:CX35) -> 705579 | CT27: kWh | CW27: kW | CX27: kW | CY27: $/hr | CZ27: kg/hr | DD27: =SUM(DI28:DI35) -> 511184 | DE27: kWh | DH27: kW | DI27: kW | DJ27: $/hr | DK27: kg/hr | DO27: =SUM(DT28:DT35) -> 386920 | DP27: kWh | DS27: kW | DT27: kW | DU27: $/hr | DV27: kg/hr | DZ27: =SUM(EE28:EE35) -> 971775.29 | EA27: kWh | ED27: kW | EE27: kW | EF27: $/hr | EG27: kg/hr
D28: MCOMP1 | E28: MCOMPR | F28: 858629 | G28: 858629 | H28: 66543.8 | I28: 297861 | N28: MCOMP1 | O28: MCOMPR | P28: 524990 | Q28: 524990 | R28: 40686.7 | S28: 182121 | X28: MCOMP1 | Y28: MCOMPR | Z28: 270842 | AA28: 270842 | AB28: 20990.2 | AC28: 93955.8 | AH28: MCOMP1 | AI28: MCOMPR | AJ28: 138593 | AK28: 138593 | AL28: 10740.9 | AM28: 48078.2 | AR28: MCOMP1 | AS28: MCOMPR | AT28: 858629 | AU28: 858629 | AV28: 66543.8 | AW28: 297861 | BC28: MCOMP1 | BD28: MCOMPR | BE28: 524990 | BF28: 524990 | BG28: 40686.7 | BH28: 182121 | BN28: MCOMP1 | BO28: MCOMPR | BP28: 270842 | BQ28: 270842 | BR28: 20990.2 | BS28: 93955.8 | BY28: MCOMP1 | BZ28: MCOMPR | CA28: 138593 | CB28: 138593 | CC28: 10740.9 | CD28: 48078.2 | CJ28: MCOMP1 | CK28: MCOMPR | CL28: 858629 | CM28: 858629 | CN28: 66543.8 | CO28: 297861 | CU28: MCOMP1 | CV28: MCOMPR | CW28: 524990 | CX28: 524990 | CY28: 40686.7 | CZ28: 182121 | DF28: MCOMP1 | DG28: MCOMPR | DH28: 270842 | DI28: 270842 | DJ28: 20990.2 | DK28: 93955.8 | DQ28: MCOMP1 | DR28: MCOMPR | DS28: 138593 | DT28: 138593 | DU28: 10740.9 | DV28: 48078.2 | EB28: MCOMP1 | EC28: MCOMPR | ED28: 858629 | EE28: 858629 | EF28: 66543.8 | EG28: 297861
D29: MCOMP2 | E29: MCOMPR | F29: 111369 | G29: 111369 | H29: 8631.06 | I29: 38634.1 | N29: MCOMP2 | O29: MCOMPR | P29: 180589 | Q29: 180589 | R29: 13995.7 | S29: 62646.9 | X29: MCOMP2 | Y29: MCOMPR | Z29: 240342 | AA29: 240342 | AB29: 18626.5 | AC29: 83375.5 | AH29: MCOMP2 | AI29: MCOMPR | AJ29: 248327 | AK29: 248327 | AL29: 19245.3 | AM29: 86145.4 | AR29: MCOMP2 | AS29: MCOMPR | AT29: 111369 | AU29: 111369 | AV29: 8631.06 | AW29: 38634.1 | BC29: MCOMP2 | BD29: MCOMPR | BE29: 180589 | BF29: 180589 | BG29: 13995.7 | BH29: 62646.9 | BN29: MCOMP2 | BO29: MCOMPR | BP29: 240342 | BQ29: 240342 | BR29: 18626.5 | BS29: 83375.5 | BY29: MCOMP2 | BZ29: MCOMPR | CA29: 248327 | CB29: 248327 | CC29: 19245.3 | CD29: 86145.4 | CJ29: MCOMP2 | CK29: MCOMPR | CL29: 111369 | CM29: 111369 | CN29: 8631.06 | CO29: 38634.1 | CU29: MCOMP2 | CV29: MCOMPR | CW29: 180589 | CX29: 180589 | CY29: 13995.7 | CZ29: 62646.9 | DF29: MCOMP2 | DG29: MCOMPR | DH29: 240342 | DI29: 240342 | DJ29: 18626.5 | DK29: 83375.5 | DQ29: MCOMP2 | DR29: MCOMPR | DS29: 248327 | DT29: 248327 | DU29: 19245.3 | DV29: 86145.4 | EB29: MCOMP2 | EC29: MCOMPR | ED29: 111369 | EE29: 111369 | EF29: 8631.06 | EG29: 38634.1
AR30: P-1 | AS30: PUMP | AT30: 312.438 | AU30: 312.438 | AV30: 24.214 | AW30: 108.386 | BC30: P-1 | BD30: PUMP | BE30: 273.893 | BF30: 273.893 | BG30: 21.2267 | BH30: 95.0143 | BN30: P-1 | BO30: PUMP | BP30: 201.742 | BQ30: 201.742 | BR30: 15.635 | BS30: 69.9851 | BY30: P-1 | BZ30: PUMP | CA30: 203.686 | CB30: 203.686 | CC30: 15.7857 | CD30: 70.6593 | EB30: P-1 | EC30: PUMP | ED30: 8.56357 | EE30: 8.56357 | EF30: 0.663677 | EG30: 2.97073
AR31: B7 | AS31: COMPR | AT31: 59650.9 | AU31: 59650.9 | AV31: 4622.95 | AW31: 20693.1 | BC31: B8 | BD31: COMPR | BE31: 53670.5 | BF31: 53670.5 | BG31: 4159.46 | BH31: 18618.5 | BN31: B10 | BO31: COMPR | BP31: 45766.6 | BQ31: 45766.6 | BR31: 3546.91 | BS31: 15876.6 | BY31: B8 | BZ31: COMPR | CA31: 42243.4 | CB31: 42243.4 | CC31: 3273.86 | CD31: 14654.4 | EB31: B7 | EC31: COMPR | ED31: 1768.73 | EE31: 1768.73 | EF31: 137.077 | EG31: 613.579
B36: Fired heat | D36: Block ID | E36: Block type | F36: Duty | G36: Usage | H36: Cost | I36: CO2 emission rate | L36: Fired heat | N36: Block ID | O36: Block type | P36: Duty | Q36: Usage | R36: Cost | S36: CO2 emission rate | V36: Fired heat | X36: Block ID | Y36: Block type | Z36: Duty | AA36: Usage | AB36: Cost | AC36: CO2 emission rate | AF36: Fired heat | AH36: Block ID | AI36: Block type | AJ36: Duty | AK36: Usage | AL36: Cost | AM36: CO2 emission rate | AP36: Fired heat | AR36: Block ID | AS36: Block type | AT36: Duty | AU36: Usage | AV36: Cost | AW36: CO2 emission rate | BA36: Fired heat | BC36: Block ID | BD36: Block type | BE36: Duty | BF36: Usage | BG36: Cost | BH36: CO2 emission rate | BL36: Fired heat | BN36: Block ID | BO36: Block type | BP36: Duty | BQ36: Usage | BR36: Cost | BS36: CO2 emission rate | BW36: Fired heat | BY36: Block ID | BZ36: Block type | CA36: Duty | CB36: Usage | CC36: Cost | CD36: CO2 emission rate | CH36: Fired heat | CJ36: Block ID | CK36: Block type | CL36: Duty | CM36: Usage | CN36: Cost | CO36: CO2 emission rate | CS36: Fired heat | CU36: Block ID | CV36: Block type | CW36: Duty | CX36: Usage | CY36: Cost | CZ36: CO2 emission rate | DD36: Fired heat | DF36: Block ID | DG36: Block type | DH36: Duty | DI36: Usage | DJ36: Cost | DK36: CO2 emission rate | DO36: Fired heat | DQ36: Block ID | DR36: Block type | DS36: Duty | DT36: Usage | DU36: Cost | DV36: CO2 emission rate | DZ36: Fired heat | EB36: Block ID | EC36: Block type | ED36: Duty | EE36: Usage | EF36: Cost | EG36: CO2 emission rate
B37: =SUM(F38:F42) -> 0 | C37: kW | F37: kW | G37: kg/day | H37: $/hr | I37: kg/hr | L37: =SUM(P38:P42) -> 0 | M37: kW | P37: kW | Q37: kg/hr | R37: $/hr | S37: kg/hr | V37: =SUM(Z38:Z42) -> 0 | W37: kW | Z37: kW | AA37: kg/hr | AB37: $/hr | AC37: kg/hr | AF37: =SUM(AJ38:AJ42) -> 0 | AG37: kW | AJ37: kW | AK37: kg/hr | AL37: $/hr | AM37: kg/hr | AP37: =SUM(AT38:AT42) -> 0 | AQ37: kW | AT37: kW | AU37: kg/hr | AV37: $/hr | AW37: kg/hr | BA37: =SUM(BE38:BE42) -> 0 | BB37: kW | BE37: kW | BF37: kg/hr | BG37: $/hr | BH37: kg/hr | BL37: =SUM(BP38:BP42) -> 0 | BM37: kW | BP37: kW | BQ37: kg/hr | BR37: $/hr | BS37: kg/hr | BW37: =SUM(CA38:CA42) -> 0 | BX37: kW | CA37: kW | CB37: kg/hr | CC37: $/hr | CD37: kg/hr | CH37: =SUM(CL38:CL42) -> 0 | CI37: kW | CL37: kW | CM37: kg/hr | CN37: $/hr | CO37: kg/hr | CS37: =SUM(CW38:CW42) -> 0 | CT37: kW | CW37: kW | CX37: kg/hr | CY37: $/hr | CZ37: kg/hr | DD37: =SUM(DH38:DH42) -> 0 | DE37: kW | DH37: kW | DI37: kg/hr | DJ37: $/hr | DK37: kg/hr | DO37: =SUM(DS38:DS42) -> 0 | DP37: kW | DS37: kW | DT37: kg/hr | DU37: $/hr | DV37: kg/hr | DZ37: =SUM(ED38:ED42) -> 0 | EA37: kW | ED37: kW | EE37: kg/hr | EF37: $/hr | EG37: kg/hr
B43: High-pressure steam | D43: Block ID | E43: Block type | F43: Duty | G43: Usage | H43: Cost | I43: CO2 emission rate | L43: High-pressure steam | N43: Block ID | O43: Block type | P43: Duty | Q43: Usage | R43: Cost | S43: CO2 emission rate | V43: High-pressure steam | X43: Block ID | Y43: Block type | Z43: Duty | AA43: Usage | AB43: Cost | AC43: CO2 emission rate | AF43: High-pressure steam | AH43: Block ID | AI43: Block type | AJ43: Duty | AK43: Usage | AL43: Cost | AM43: CO2 emission rate | AP43: High-pressure steam | AR43: Block ID | AS43: Block type | AT43: Duty | AU43: Usage | AV43: Cost | AW43: CO2 emission rate | BA43: High-pressure steam | BC43: Block ID | BD43: Block type | BE43: Duty | BF43: Usage | BG43: Cost | BH43: CO2 emission rate | BL43: High-pressure steam | BN43: Block ID | BO43: Block type | BP43: Duty | BQ43: Usage | BR43: Cost | BS43: CO2 emission rate | BW43: High-pressure steam | BY43: Block ID | BZ43: Block type | CA43: Duty | CB43: Usage | CC43: Cost | CD43: CO2 emission rate | CH43: High-pressure steam | CJ43: Block ID | CK43: Block type | CL43: Duty | CM43: Usage | CN43: Cost | CO43: CO2 emission rate | CS43: High-pressure steam | CU43: Block ID | CV43: Block type | CW43: Duty | CX43: Usage | CY43: Cost | CZ43: CO2 emission rate | DD43: High-pressure steam | DF43: Block ID | DG43: Block type | DH43: Duty | DI43: Usage | DJ43: Cost | DK43: CO2 emission rate | DO43: High-pressure steam | DQ43: Block ID | DR43: Block type | DS43: Duty | DT43: Usage | DU43: Cost | DV43: CO2 emission rate | DZ43: High-pressure steam | EB43: Block ID | EC43: Block type | ED43: Duty | EE43: Usage | EF43: Cost | EG43: CO2 emission rate
B44: =SUM(G45:G49) -> 0 | C44: ton/h | F44: kW | G44: tonne/hr | H44: $/hr | I44: kg/hr | L44: =SUM(Q45:Q49) -> 0 | M44: ton/h | P44: kW | Q44: tonne/hr | R44: $/hr | S44: kg/hr | V44: =SUM(AA45:AA49) -> 0 | W44: ton/h | Z44: kW | AA44: tonne/hr | AB44: $/hr | AC44: kg/hr | AF44: =SUM(AK45:AK49) -> 0 | AG44: ton/h | AJ44: kW | AK44: tonne/hr | AL44: $/hr | AM44: kg/hr | AP44: =SUM(AU45:AU49) -> 0 | AQ44: ton/h | AT44: kW | AU44: tonne/hr | AV44: $/hr | AW44: kg/hr | BA44: =SUM(BF45:BF49) -> 0 | BB44: ton/h | BE44: kW | BF44: tonne/hr | BG44: $/hr | BH44: kg/hr | BL44: =SUM(BQ45:BQ49) -> 0 | BM44: ton/h | BP44: kW | BQ44: tonne/hr | BR44: $/hr | BS44: kg/hr | BW44: =SUM(CB45:CB49) -> 0 | BX44: ton/h | CA44: kW | CB44: tonne/hr | CC44: $/hr | CD44: kg/hr | CH44: =SUM(CM45:CM49) -> 0 | CI44: ton/h | CL44: kW | CM44: tonne/hr | CN44: $/hr | CO44: kg/hr | CS44: =SUM(CX45:CX49) -> 0 | CT44: ton/h | CW44: kW | CX44: tonne/hr | CY44: $/hr | CZ44: kg/hr | DD44: =SUM(DI45:DI49) -> 0 | DE44: ton/h | DH44: kW | DI44: tonne/hr | DJ44: $/hr | DK44: kg/hr | DO44: =SUM(DT45:DT49) -> 0 | DP44: ton/h | DS44: kW | DT44: tonne/hr | DU44: $/hr | DV44: kg/hr | DZ44: =SUM(EE45:EE49) -> 0 | EA44: ton/h | ED44: kW | EE44: tonne/hr | EF44: $/hr | EG44: kg/hr
B45: =SUM(F45:F49) -> 0 | C45: kW | L45: =SUM(P45:P49) -> 0 | M45: kW | V45: =SUM(Z45:Z49) -> 0 | W45: kW | AF45: =SUM(AJ45:AJ49) -> 0 | AG45: kW | AP45: =SUM(AT45:AT49) -> 0 | AQ45: kW | BA45: =SUM(BE45:BE49) -> 0 | BB45: kW | BL45: =SUM(BP45:BP49) -> 0 | BM45: kW | BW45: =SUM(CA45:CA49) -> 0 | BX45: kW | CH45: =SUM(CL45:CL49) -> 0 | CI45: kW | CS45: =SUM(CW45:CW49) -> 0 | CT45: kW | DD45: =SUM(DH45:DH49) -> 0 | DE45: kW | DO45: =SUM(DS45:DS49) -> 0 | DP45: kW | DZ45: =SUM(ED45:ED49) -> 0 | EA45: kW
B50: Low-pressure steam | D50: Block ID | E50: Block type | F50: Duty | G50: Usage | H50: Cost | I50: CO2 emission rate | L50: Low-pressure steam | N50: Block ID | O50: Block type | P50: Duty | Q50: Usage | R50: Cost | S50: CO2 emission rate | V50: Low-pressure steam | X50: Block ID | Y50: Block type | Z50: Duty | AA50: Usage | AB50: Cost | AC50: CO2 emission rate | AF50: Low-pressure steam | AH50: Block ID | AI50: Block type | AJ50: Duty | AK50: Usage | AL50: Cost | AM50: CO2 emission rate | AP50: Low-pressure steam | AR50: Block ID | AS50: Block type | AT50: Duty | AU50: Usage | AV50: Cost | AW50: CO2 emission rate | BA50: Low-pressure steam | BC50: Block ID | BD50: Block type | BE50: Duty | BF50: Usage | BG50: Cost | BH50: CO2 emission rate | BL50: Low-pressure steam | BN50: Block ID | BO50: Block type | BP50: Duty | BQ50: Usage | BR50: Cost | BS50: CO2 emission rate | BW50: Low-pressure steam | BY50: Block ID | BZ50: Block type | CA50: Duty | CB50: Usage | CC50: Cost | CD50: CO2 emission rate | CH50: Low-pressure steam | CJ50: Block ID | CK50: Block type | CL50: Duty | CM50: Usage | CN50: Cost | CO50: CO2 emission rate | CS50: Low-pressure steam | CU50: Block ID | CV50: Block type | CW50: Duty | CX50: Usage | CY50: Cost | CZ50: CO2 emission rate | DD50: Low-pressure steam | DF50: Block ID | DG50: Block type | DH50: Duty | DI50: Usage | DJ50: Cost | DK50: CO2 emission rate | DO50: Low-pressure steam | DQ50: Block ID | DR50: Block type | DS50: Duty | DT50: Usage | DU50: Cost | DV50: CO2 emission rate | DZ50: Low-pressure steam | EB50: Block ID | EC50: Block type | ED50: Duty | EE50: Usage | EF50: Cost | EG50: CO2 emission rate
B51: =SUM(G52:G56) -> 0 | C51: ton/h | F51: kW | G51: tonne/hr | H51: $/hr | I51: kg/hr | L51: =SUM(Q52:Q56) -> 0 | M51: ton/h | P51: kW | Q51: tonne/hr | R51: $/hr | S51: kg/hr | V51: =SUM(AA52:AA56) -> 0 | W51: ton/h | Z51: kW | AA51: tonne/hr | AB51: $/hr | AC51: kg/hr | AF51: =SUM(AK52:AK56) -> 0 | AG51: ton/h | AJ51: kW | AK51: tonne/hr | AL51: $/hr | AM51: kg/hr | AP51: =SUM(AU52:AU56) -> 787.09123 | AQ51: ton/h | AT51: kW | AU51: tonne/hr | AV51: $/hr | AW51: kg/hr | BA51: =SUM(BF52:BF56) -> 649.23816 | BB51: ton/h | BE51: kW | BF51: tonne/hr | BG51: $/hr | BH51: kg/hr | BL51: =SUM(BQ52:BQ56) -> 529.53666 | BM51: ton/h | BP51: kW | BQ51: tonne/hr | BR51: $/hr | BS51: kg/hr | BW51: =SUM(CB52:CB56) -> 446.3177 | BX51: ton/h | CA51: kW | CB51: tonne/hr | CC51: $/hr | CD51: kg/hr | CH51: =SUM(CM52:CM56) -> 0 | CI51: ton/h | CL51: kW | CM51: tonne/hr | CN51: $/hr | CO51: kg/hr | CS51: =SUM(CX52:CX56) -> 0 | CT51: ton/h | CW51: kW | CX51: tonne/hr | CY51: $/hr | CZ51: kg/hr | DD51: =SUM(DI52:DI56) -> 0 | DE51: ton/h | DH51: kW | DI51: tonne/hr | DJ51: $/hr | DK51: kg/hr | DO51: =SUM(DT52:DT56) -> 0 | DP51: ton/h | DS51: kW | DT51: tonne/hr | DU51: $/hr | DV51: kg/hr | DZ51: =SUM(EE52:EE56) -> 22.298386 | EA51: ton/h | ED51: kW | EE51: tonne/hr | EF51: $/hr | EG51: kg/hr
B52: =SUM(F52:F56) -> 0 | C52: kW | L52: =SUM(P52:P56) -> 0 | M52: kW | V52: =SUM(Z52:Z56) -> 0 | W52: kW | AF52: =SUM(AJ52:AJ56) -> 0 | AG52: kW | AP52: =SUM(AT52:AT56) -> 479225.42 | AQ52: kW | AR52: REG | AS52: RADFRAC | AT52: 479225.42 | AU52: 787.09123 | AV52: 4604.26 | AW52: 159339 | BA52: =SUM(BE52:BE56) -> 395292.71 | BB52: kW | BC52: REG | BD52: RADFRAC | BE52: 395292.71 | BF52: 649.23816 | BG52: 4041.12 | BH52: 139850 | BL52: =SUM(BP52:BP56) -> 322411.71 | BM52: kW | BP52: 322411.71 | BQ52: 529.53666 | BW52: =SUM(CA52:CA56) -> 271743.32 | BX52: kW | BY52: REG | BZ52: RADFRAC | CA52: 271743.32 | CB52: 446.3177 | CH52: =SUM(CL52:CL56) -> 0 | CI52: kW | CS52: =SUM(CW52:CW56) -> 0 | CT52: kW | DD52: =SUM(DH52:DH56) -> 0 | DE52: kW | DO52: =SUM(DS52:DS56) -> 0 | DP52: kW | DZ52: =SUM(ED52:ED56) -> 13576.512 | EA52: kW | EB52: REG | EC52: RADFRAC | ED52: 13576.512 | EE52: 22.298386 | EF52: 144.587 | EG52: 5003.68
B57: Refrigeration | D57: Block ID | E57: Block type | F57: Duty | G57: Usage | H57: Cost | I57: CO2 emission rate | L57: Refrigeration | N57: Block ID | O57: Block type | P57: Duty | Q57: Usage | R57: Cost | S57: CO2 emission rate | V57: Refrigeration | X57: Block ID | Y57: Block type | Z57: Duty | AA57: Usage | AB57: Cost | AC57: CO2 emission rate | AF57: Refrigeration | AH57: Block ID | AI57: Block type | AJ57: Duty | AK57: Usage | AL57: Cost | AM57: CO2 emission rate | AP57: Refrigeration | AR57: Block ID | AS57: Block type | AT57: Duty | AU57: Usage | AV57: Cost | AW57: CO2 emission rate | BA57: Refrigeration | BC57: Block ID | BD57: Block type | BE57: Duty | BF57: Usage | BG57: Cost | BH57: CO2 emission rate | BL57: Refrigeration | BN57: Block ID | BO57: Block type | BP57: Duty | BQ57: Usage | BR57: Cost | BS57: CO2 emission rate | BW57: Refrigeration | BY57: Block ID | BZ57: Block type | CA57: Duty | CB57: Usage | CC57: Cost | CD57: CO2 emission rate | CH57: Refrigeration | CJ57: Block ID | CK57: Block type | CL57: Duty | CM57: Usage | CN57: Cost | CO57: CO2 emission rate | CS57: Refrigeration | CU57: Block ID | CV57: Block type | CW57: Duty | CX57: Usage | CY57: Cost | CZ57: CO2 emission rate | DD57: Refrigeration | DF57: Block ID | DG57: Block type | DH57: Duty | DI57: Usage | DJ57: Cost | DK57: CO2 emission rate | DO57: Refrigeration | DQ57: Block ID | DR57: Block type | DS57: Duty | DT57: Usage | DU57: Cost | DV57: CO2 emission rate | DZ57: Refrigeration | EB57: Block ID | EC57: Block type | ED57: Duty | EE57: Usage | EF57: Cost | EG57: CO2 emission rate
B58: =SUM(F59:F66) -> 238557.95 | C58: kWh | F58: kW | G58: kg/hr | H58: $/hr | I58: kg/hr | L58: =SUM(P59:P66) -> 169532.29 | M58: kWh | P58: kW | Q58: kg/hr | R58: $/hr | S58: kg/hr | V58: =SUM(Z59:Z66) -> 174006.8 | W58: kWh | Z58: kW | AA58: kg/hr | AB58: $/hr | AC58: kg/hr | AF58: =SUM(AJ59:AJ66) -> 170031.17 | AG58: kWh | AJ58: kW | AK58: kg/hr | AL58: $/hr | AM58: kg/hr | AP58: =SUM(AT59:AT66) -> 238557.95 | AQ58: kWh | AT58: kW | AU58: kg/hr | AV58: $/hr | AW58: kg/hr | BA58: =SUM(BE59:BE66) -> 169532.29 | BB58: kWh | BE58: kW | BF58: kg/hr | BG58: $/hr | BH58: kg/hr | BL58: =SUM(BP59:BP66) -> 174006.8 | BM58: kWh | BP58: kW | BQ58: kg/hr | BR58: $/hr | BS58: kg/hr | BW58: =SUM(CA59:CA66) -> 170031.17 | BX58: kWh | CA58: kW | CB58: kg/hr | CC58: $/hr | CD58: kg/hr | CH58: =SUM(CL59:CL66) -> 238557.95 | CI58: kWh | CL58: kW | CM58: kg/hr | CN58: $/hr | CO58: kg/hr | CS58: =SUM(CW59:CW66) -> 169532.29 | CT58: kWh | CW58: kW | CX58: kg/hr | CY58: $/hr | CZ58: kg/hr | DD58: =SUM(DH59:DH66) -> 174006.8 | DE58: kWh | DH58: kW | DI58: kg/hr | DJ58: $/hr | DK58: kg/hr | DO58: =SUM(DS59:DS66) -> 170031.17 | DP58: kWh | DS58: kW | DT58: kg/hr | DU58: $/hr | DV58: kg/hr | DZ58: =SUM(ED59:ED66) -> 238557.95 | EA58: kWh | ED58: kW | EE58: kg/hr | EF58: $/hr | EG58: kg/hr
D59: V3 | E59: FLASH2 | F59: 19369.6 | G59: 51998800 | H59: 620.601 | I59: 3897.23 | N59: V3 | O59: FLASH2 | P59: 19701.5 | Q59: 52889900 | R59: 631.236 | S59: 3964.02 | X59: V3 | Y59: FLASH2 | Z59: 22838.6 | AA59: 61311700 | AB59: 731.749 | AC59: 4595.21 | AH59: V3 | AI59: FLASH2 | AJ59: 28362.4 | AK59: 76140600 | AL59: 908.73 | AM59: 5706.62 | AR59: V3 | AS59: FLASH2 | AT59: 19369.6 | AU59: 51998800 | AV59: 620.601 | AW59: 3897.23 | BC59: V3 | BD59: FLASH2 | BE59: 19701.5 | BF59: 52889900 | BG59: 631.236 | BH59: 3964.02 | BN59: V3 | BO59: FLASH2 | BP59: 22838.6 | BQ59: 61311700 | BR59: 731.749 | BS59: 4595.21 | BY59: V3 | BZ59: FLASH2 | CA59: 28362.4 | CB59: 76140600 | CC59: 908.73 | CD59: 5706.62 | CJ59: V3 | CK59: FLASH2 | CL59: 19369.6 | CM59: 51998800 | CN59: 620.601 | CO59: 3897.23 | CU59: V3 | CV59: FLASH2 | CW59: 19701.5 | CX59: 52889900 | CY59: 631.236 | CZ59: 3964.02 | DF59: V3 | DG59: FLASH2 | DH59: 22838.6 | DI59: 61311700 | DJ59: 731.749 | DK59: 4595.21 | DQ59: V3 | DR59: FLASH2 | DS59: 28362.4 | DT59: 76140600 | DU59: 908.73 | DV59: 5706.62 | EB59: V3 | EC59: FLASH2 | ED59: 19369.6 | EE59: 51998800 | EF59: 620.601 | EG59: 3897.23
D60: V4 | E60: FLASH2 | F60: 77737.3 | G60: 208691000 | H60: 2490.7 | I60: 15641 | N60: V4 | O60: FLASH2 | P60: 62776.1 | Q60: 168527000 | R60: 2011.35 | S60: 12630.8 | X60: V4 | Y60: FLASH2 | Z60: 59537.9 | AA60: 159833000 | AB60: 1907.59 | AC60: 11979.3 | AH60: V4 | AI60: FLASH2 | AJ60: 81160.5 | AK60: 217881000 | AL60: 2600.38 | AM60: 16329.8 | AR60: V4 | AS60: FLASH2 | AT60: 77737.3 | AU60: 208691000 | AV60: 2490.7 | AW60: 15641 | BC60: V4 | BD60: FLASH2 | BE60: 62776.1 | BF60: 168527000 | BG60: 2011.35 | BH60: 12630.8 | BN60: V4 | BO60: FLASH2 | BP60: 59537.9 | BQ60: 159833000 | BR60: 1907.59 | BS60: 11979.3 | BY60: V4 | BZ60: FLASH2 | CA60: 81160.5 | CB60: 217881000 | CC60: 2600.38 | CD60: 16329.8 | CJ60: V4 | CK60: FLASH2 | CL60: 77737.3 | CM60: 208691000 | CN60: 2490.7 | CO60: 15641 | CU60: V4 | CV60: FLASH2 | CW60: 62776.1 | CX60: 168527000 | CY60: 2011.35 | CZ60: 12630.8 | DF60: V4 | DG60: FLASH2 | DH60: 59537.9 | DI60: 159833000 | DJ60: 1907.59 | DK60: 11979.3 | DQ60: V4 | DR60: FLASH2 | DS60: 81160.5 | DT60: 217881000 | DU60: 2600.38 | DV60: 16329.8 | EB60: V4 | EC60: FLASH2 | ED60: 77737.3 | EE60: 208691000 | EF60: 2490.7 | EG60: 15641
D61: V5 | E61: FLASH2 | F61: 65954.6 | G61: 177059000 | H61: 2113.19 | I61: 13270.3 | N61: V5 | O61: FLASH2 | P61: 48031.6 | Q61: 128944000 | R61: 1538.93 | S61: 9664.13 | X61: V5 | Y61: FLASH2 | Z61: 34337.4 | AA61: 92180900 | AB61: 1100.17 | AC61: 6908.81 | AH61: V5 | AI61: FLASH2 | AJ61: 10858 | AK61: 29148900 | AL61: 347.89 | AM61: 2184.67 | AR61: V5 | AS61: FLASH2 | AT61: 65954.6 | AU61: 177059000 | AV61: 2113.19 | AW61: 13270.3 | BC61: V5 | BD61: FLASH2 | BE61: 48031.6 | BF61: 128944000 | BG61: 1538.93 | BH61: 9664.13 | BN61: V5 | BO61: FLASH2 | BP61: 34337.4 | BQ61: 92180900 | BR61: 1100.17 | BS61: 6908.81 | BY61: V5 | BZ61: FLASH2 | CA61: 10858 | CB61: 29148900 | CC61: 347.89 | CD61: 2184.67 | CJ61: V5 | CK61: FLASH2 | CL61: 65954.6 | CM61: 177059000 | CN61: 2113.19 | CO61: 13270.3 | CU61: V5 | CV61: FLASH2 | CW61: 48031.6 | CX61: 128944000 | CY61: 1538.93 | CZ61: 9664.13 | DF61: V5 | DG61: FLASH2 | DH61: 34337.4 | DI61: 92180900 | DJ61: 1100.17 | DK61: 6908.81 | DQ61: V5 | DR61: FLASH2 | DS61: 10858 | DT61: 29148900 | DU61: 347.89 | DV61: 2184.67 | EB61: V5 | EC61: FLASH2 | ED61: 65954.6 | EE61: 177059000 | EF61: 2113.19 | EG61: 13270.3
...

Sheet 5. HEN_equip
A1: EQUIP.ICS (Equipment)
A3: Area Name | B3: Component Name | C3: Component Type | D3: Total Direct Cost | E3: Equipment Cost | F3: Equipment Weight | G3: Installed Weight
D4: (USD) | E4: (USD) | F4: LBS | G4: LBS
A11: R1 | B11: R1.RADIANT1 | C11: DHE TEMA EXCH
A12: R1 | B12: R1.M5 | C12: C | D12: 0 | E12: 0 | F12: 0 | G12: 0
A13: R1 | B13: R1.M402 | C13: C | D13: 0 | E13: 0 | F13: 0 | G13: 0
A14: R1 | B14: R1.DECOKING | C14: DAT REACTOR
A15: R1 | B15: R1.CONVECT2 | C15: DHE TEMA EXCH
A16: R1 | B16: R1.CONVECT1 | C16: DHE TEMA EXCH
A17: R1 | B17: R1.COMBUST | C17: DAT REACTOR
A18: R1 | B18: R1.B6 | C18: C | D18: 0 | E18: 0 | F18: 0 | G18: 0
A19: R1 | B19: R1.B1 | C19: DVT CYLINDER
A21: Miscellaneous Flowsheet Area | B21: VAL1 | C21: C | D21: 0 | E21: 0 | F21: 0 | G21: 0
A22: Miscellaneous Flowsheet Area | B22: V5-flash vessel | C22: DVT CYLINDER | D22: 449600 | E22: 165100 | F22: 77400 | G22: 123720
A23: Miscellaneous Flowsheet Area | B23: V4-flash vessel | C23: DVT CYLINDER | D23: 827300 | E23: 465200 | F23: 201800 | G23: 260882
A24: Miscellaneous Flowsheet Area | B24: V3-flash vessel | C24: DVT CYLINDER | D24: 812700 | E24: 583200 | F24: 245600 | G24: 284078
A25: Miscellaneous Flowsheet Area | B25: V2-flash vessel | C25: DVT CYLINDER | D25: 879100 | E25: 674200 | F25: 288900 | G25: 324361
A26: Miscellaneous Flowsheet Area | B26: V1-flash vessel | C26: DVT CYLINDER | D26: 3166900 | E26: 2366000 | F26: 1062700 | G26: 1216094
A27: Miscellaneous Flowsheet Area | B27: T3-bottoms split | C27: C | D27: 0 | E27: 0 | F27: 0 | G27: 0
A28: Miscellaneous Flowsheet Area | B28: T3-cond | C28: DHE TEMA EXCH | D28: 897800 | E28: 785600 | F28: 251000 | G28: 267561
A29: Miscellaneous Flowsheet Area | B29: T3-cond acc | C29: DHT HORIZ DRUM | D29: 348500 | E29: 58600 | F29: 17500 | G29: 60908
A30: Miscellaneous Flowsheet Area | B30: T3-overhead split | C30: C | D30: 0 | E30: 0 | F30: 0 | G30: 0
A31: Miscellaneous Flowsheet Area | B31: T3-reb | C31: DRB U TUBE | D31: 955000 | E31: 777800 | F31: 224700 | G31: 251939
A32: Miscellaneous Flowsheet Area | B32: T3-reflux pump | C32: DCP CENTRIF | D32: 116200 | E32: 33900 | F32: 2500 | G32: 15774
... A47: Miscellaneous Flowsheet Area | B47: T1-tower | C47: DTW TOWER | D47: 359100 | E47: 158600 | F47: 56300 | G47: 83523
A48: Miscellaneous Flowsheet Area | B48: MCOMP2 | C48: DGC CENTRIF
A49: Miscellaneous Flowsheet Area | B49: MCOMP1 | C49: DGC CENTRIF
A50: Miscellaneous Flowsheet Area | B50: M4 | C50: C | D50: 0 | E50: 0 | F50: 0 | G50: 0
A51: Miscellaneous Flowsheet Area | B51: M3 | C51: C | D51: 0 | E51: 0 | F51: 0 | G51: 0
A52: Miscellaneous Flowsheet Area | B52: M2 | C52: C | D52: 0 | E52: 0 | F52: 0 | G52: 0
A53: Miscellaneous Flowsheet Area | B53: M1 | C53: C | D53: 0 | E53: 0 | F53: 0 | G53: 0
A54: Miscellaneous Flowsheet Area | B54: HX1 | C54: DHE TEMA EXCH
A55: Miscellaneous Flowsheet Area | B55: E9 | C55: DHE TEMA EXCH | D55: 799000 | E55: 770000 | F55: 245500 | G55: 249322
A56: Miscellaneous Flowsheet Area | B56: E8 | C56: DHE TEMA EXCH | D56: 667300 | E56: 646300 | F56: 180000 | G56: 182261
A57: Miscellaneous Flowsheet Area | B57: E7 | C57: DHE TEMA EXCH | D57: 1435300 | E57: 1316700 | F57: 373600 | G57: 391318
A58: Miscellaneous Flowsheet Area | B58: E6 | C58: DHE TEMA EXCH | D58: 1191300 | E58: 1112400 | F58: 314800 | G58: 327046
A59: Miscellaneous Flowsheet Area | B59: E5 | C59: DHE TEMA EXCH | D59: 970300 | E59: 949000 | F59: 272400 | G59: 274711
A60: Miscellaneous Flowsheet Area | B60: E4 | C60: DHE TEMA EXCH | D60: 252900 | E60: 236100 | F60: 66900 | G60: 68962
A61: Miscellaneous Flowsheet Area | B61: E3 | C61: DHE TEMA EXCH
A62: Miscellaneous Flowsheet Area | B62: E2 | C62: DHE TEMA EXCH | D62: 17682200 | E62: 7976800 | F62: 1048800 | G62: 1675328
...

Sheet 3. UPC & MSP (fixed)
A1: 1. Assumption and parameters
B3: ASSUMPTION AND PARAMETERS
B4: Location | E4: North America
B5: System Cost Base Date | E5: 1Q 16
B6: Project Type | E6: Grass roots/Clear field
B7: Plant lifetime (y) | E7: 30
B8: Annual operating hours (h) | E8: 8000
B9: Depreciation method | E9: Straight line
B10: Interest rate (%) | E10: 0.08
B11: Tax rate (%) | E11: 0.35
B12: Operating charges [% of operating labor cost] | E12: 0.15
B13: Plant overhead [% of labor and maintenance costs] | E13: 0.25
B14: G&A [% of fixed-operating cost] | E14: 0.06
B15: Capital charge factor | E15: =E10*POWER(1+E10,E7)/(POWER(1+E10,E7)-1) -> 0.088827433
A18: 2. Production Costs, UPC, and MSP
E20: Previous | F20: Case 1 | G20: Case 2 | H20: Case 3 | I20: Case 4
B21: 1. Total capital investment cost (TCI) ($) | D21: =SUBTOTAL(9,D22:D36) -> 5.04 | E21: =SUBTOTAL(9,E22:E36) -> 2.5298291e+09 | F21: =SUBTOTAL(9,F22:F36) -> 3.0959305e+09 | G21: =SUBTOTAL(9,G22:G36) -> 2.2739022e+09 | H21: =SUBTOTAL(9,H22:H36) -> 1.9751287e+09 | I21: =SUBTOTAL(9,I22:I36) -> 1.7921087e+09
B22: 1.1. Direct plan cost | D22: =SUBTOTAL(9,D23:D30) -> 3.6 | E22: =SUBTOTAL(9,E23:E30) -> 1.8070208e+09 | F22: =SUBTOTAL(9,F23:F30) -> 2.2113789e+09 | G22: =SUBTOTAL(9,G23:G30) -> 1.6242158e+09 | H22: =SUBTOTAL(9,H23:H30) -> 1.4108062e+09 | I22: =SUBTOTAL(9,I23:I30) -> 1.2800776e+09
B23: Purchased equipment (PE) | D23: 1 | E23: 5.0195021e+08 | F23: 6.1427193e+08 | G23: 4.5117106e+08 | H23: 3.9189061e+08 | I23: 3.5557711e+08
B24: Equipment setting | D24: 0.47 | E24: =$D24*E$23/$D$23 -> 2.359166e+08 | F24: =$D24*F$23/$D$23 -> 2.8870781e+08 | G24: =$D24*G$23/$D$23 -> 2.120504e+08 | H24: =$D24*H$23/$D$23 -> 1.8418859e+08 | I24: =$D24*I$23/$D$23 -> 1.6712124e+08
B25: Instrumentation and control | D25: 0.36 | E25: =$D25*E$23/$D$23 -> 1.8070208e+08 | F25: =$D25*F$23/$D$23 -> 2.2113789e+08 | G25: =$D25*G$23/$D$23 -> 1.6242158e+08 | H25: =$D25*H$23/$D$23 -> 1.4108062e+08 | I25: =$D25*I$23/$D$23 -> 1.2800776e+08
B26: Piping | D26: 0.68 | E26: =$D26*E$23/$D$23 -> 3.4132614e+08 | F26: =$D26*F$23/$D$23 -> 4.1770491e+08 | G26: =$D26*G$23/$D$23 -> 3.0679632e+08 | H26: =$D26*H$23/$D$23 -> 2.6648561e+08 | I26: =$D26*I$23/$D$23 -> 2.4179244e+08
B27: Electrical installation | D27: 0.11 | E27: =$D27*E$23/$D$23 -> 55214523 | F27: =$D27*F$23/$D$23 -> 67569912 | G27: =$D27*G$23/$D$23 -> 49628817 | H27: =$D27*H$23/$D$23 -> 43107967 | I27: =$D27*I$23/$D$23 -> 39113483
B28: Building and building services | D28: 0.18 | E28: =$D28*E$23/$D$23 -> 90351038 | F28: =$D28*F$23/$D$23 -> 1.1056895e+08 | G28: =$D28*G$23/$D$23 -> 81210792 | H28: =$D28*H$23/$D$23 -> 70540310 | I28: =$D28*I$23/$D$23 -> 64003881
B29: Yard improvements | D29: 0.1 | E29: =$D29*E$23/$D$23 -> 50195021 | F29: =$D29*F$23/$D$23 -> 61427193 | G29: =$D29*G$23/$D$23 -> 45117106 | H29: =$D29*H$23/$D$23 -> 39189061 | I29: =$D29*I$23/$D$23 -> 35557711
B30: Services facilities | D30: 0.7 | E30: =$D30*E$23/$D$23 -> 3.5136515e+08 | F30: =$D30*F$23/$D$23 -> 4.2999035e+08 | G30: =$D30*G$23/$D$23 -> 3.1581975e+08 | H30: =$D30*H$23/$D$23 -> 2.7432343e+08 | I30: =$D30*I$23/$D$23 -> 2.4890398e+08
B31: 1.2. Indirect plant cost | D31: =SUBTOTAL(9,D32:D36) -> 1.44 | E31: =SUBTOTAL(9,E32:E36) -> 7.2280831e+08 | F31: =SUBTOTAL(9,F32:F36) -> 8.8455158e+08 | G31: =SUBTOTAL(9,G32:G36) -> 6.4968633e+08 | H31: =SUBTOTAL(9,H32:H36) -> 5.6432248e+08 | I31: =SUBTOTAL(9,I32:I36) -> 5.1203104e+08
B32: Engineering | D32: 0.33 | E32: =$D32*E$23/$D$23 -> 1.6564357e+08 | F32: =$D32*F$23/$D$23 -> 2.0270974e+08 | G32: =$D32*G$23/$D$23 -> 1.4888645e+08 | H32: =$D32*H$23/$D$23 -> 1.293239e+08 | I32: =$D32*I$23/$D$23 -> 1.1734045e+08
B33: Construction expenses | D33: 0.41 | E33: =$D33*E$23/$D$23 -> 2.0579959e+08 | F33: =$D33*F$23/$D$23 -> 2.5185149e+08 | G33: =$D33*G$23/$D$23 -> 1.8498014e+08 | H33: =$D33*H$23/$D$23 -> 1.6067515e+08 | I33: =$D33*I$23/$D$23 -> 1.4578662e+08
B34: Legal expenses | D34: 0.04 | E34: =$D34*E$23/$D$23 -> 20078008 | F34: =$D34*F$23/$D$23 -> 24570877 | G34: =$D34*G$23/$D$23 -> 18046843 | H34: =$D34*H$23/$D$23 -> 15675624 | I34: =$D34*I$23/$D$23 -> 14223085
B35: Contractor's fee | D35: 0.22 | E35: =$D35*E$23/$D$23 -> 1.1042905e+08 | F35: =$D35*F$23/$D$23 -> 1.3513982e+08 | G35: =$D35*G$23/$D$23 -> 99257634 | H35: =$D35*H$23/$D$23 -> 86215934 | I35: =$D35*I$23/$D$23 -> 78226965
B36: Contingency | D36: 0.44 | E36: =$D36*E$23/$D$23 -> 2.2085809e+08 | F36: =$D36*F$23/$D$23 -> 2.7027965e+08 | G36: =$D36*G$23/$D$23 -> 1.9851527e+08 | H36: =$D36*H$23/$D$23 -> 1.7243187e+08 | I36: =$D36*I$23/$D$23 -> 1.5645393e+08
B37: Annualized TCI | E37: =E21*$E$15 -> 2.2471822e+08 | F37: =F21*$E$15 -> 2.7500356e+08 | G37: =G21*$E$15 -> 2.0198489e+08 | H37: =H21*$E$15 -> 1.7544561e+08 | I37: =I21*$E$15 -> 1.5918841e+08
